Workbook

Sheet Capa_Cover
B2: AMAZON PORTUGAL DSP Modelo Financeiro / Financial Model
B5: Lisboa / Lisbon - Inicio/Start Set/Sep 2026 - Anos civis 2026 | 2027 (pressupostos lado a lado)
B7: PARAMETROS-CHAVE / KEY PARAMETERS
B8: Estrutura / Structure | F8: Semanas (Set-Out 26) + meses (Nov-Dez 26) + trimestres (2027)
B9: Pressupostos / Assumptions | F9: 2 colunas lado a lado: Valor 2026 | Valor 2027
B10: Taxa base / Base rate | F10: €17.90/h x 9h = €161.10/rota
B11: PPR | F11: 2026: €0.08 (c/ ramp) | 2027: €0.04 (so core)
B12: Rotas / Routes | F12: Ramp 5->25 (8 sem) | Pico ate 50 (Nov-Dez)
B13: Mao-de-obra / Labour | F13: Permanentes + Temporarios ETT nos picos
B14: Prazos / Terms | F14: Recebimento Amazon Net 45 | fornecedores Net 30 (editavel)
B15: Capital inicial | F15: €80,000
B16: ESTRUTURA / STRUCTURE
B17: 2 | C17: Pressupostos / Assumptions | F17: Inputs 2026 | 2027 lado a lado + calendario operacional
B18: 3 | C18: Operacao / Operations | F18: Rotas e volumes (detalhe + trimestral)
B19: 4 | C19: Receita / Revenue | F19: Taxa base, PPR, combustivel, portagens, SLS
B20: 5 | C20: Salarios / Wages | F20: Permanentes + Temporarios ETT + gestor + admin
B21: 6 | C21: Custos / Costs | F21: Mao-de-obra, frota, overheads
B22: 7 | C22: DRE / P&L | F22: Resultados (detalhe + trimestral)
B23: 8 | C23: Tesouraria / Cash Flow | F23: Fluxo de caixa e saldo (inclui impacto IVA)
B24: 9 | C24: IVA / VAT | F24: Apuramento detalhado e impacto na caixa
B25: 10 | C25: Ponto Critico / Break-Even | F25: Rotas minimas (regime 2026)

Sheet Pressupostos_Assumpt
B1: PRESSUPOSTOS / ASSUMPTIONS - Valores 2026 | 2027 lado a lado / side by side
B2: Edita a coluna do ano respetivo. Onde o valor nao muda, 2026 e 2027 sao iguais. / Edit each year column; equal where unchanged.
B4: A. RECEITA / REVENUE
B5: Parametro / Parameter | C5: Valor 2026 | D5: Valor 2027 | E5: Unidade / Unit | F5: Fonte-Nota / Source-Note
B6: Taxa horaria base / Hourly base rate | C6: 17.9 | D6: 17.9 | E6: €/h | F6: Amazon PT DSP Guide (2027: revisao anual)
B7: Duracao rota / Route duration | C7: 9 | D7: 9 | E7: h | F7: Amazon PT DSP Guide
B8: Pagamento rota (base x h) / Route payment | C8: =C6*C7 -> 161.1 | D8: =D6*D7 -> 161.1 | E8: €/rota | F8: Calculado / Calculated
B9: PPR - base / core | C9: 0.04 | D9: 0.04 | E9: €/enc | F9: Amazon PT DSP Guide
B10: PPR - incentivo ramp / ramp incentive | C10: 0.04 | D10: 0 | E10: €/enc | F10: 2027: incentivo de ramp acaba no ano 1 / ends Y1
B11: PPR total | C11: =C9+C10 -> 0.08 | D11: =D9+D10 -> 0.04 | E11: €/enc | F11: Calculado
B12: Encomendas/rota / Packages per route | C12: 86 | D12: 86 | E12: enc | F12: Amazon PT DSP Guide
B13: Km por rota / km per route | C13: 70 | D13: 70 | E13: km | F13: Amazon PT DSP Guide
B14: Preco gasoleo / Diesel price | C14: 1.65 | D14: 1.7 | E14: €/L | F14: DGEG (2027: estimativa subida)
B15: Consumo / Consumption | C15: 10 | D15: 10 | E15: L/100km | F15: Est. Sprinter/Crafter
B16: Reembolso combustivel/rota / Fuel reimb. | C16: =C13*(C14/100)*C15 -> 11.55 | D16: =D13*(D14/100)*D15 -> 11.9 | E16: €/rota | F16: Calculado
B17: Portagens/rota / Tolls per route | C17: 3.5 | D17: 3.5 | E17: €/rota | F17: Est. A1/A8 Lisboa
B18: Incentivo SLS / SLS incentive (mensal) | C18: 500 | D18: 500 | E18: €/mes | F18: Sujeito a desempenho
B20: B. OPERACAO / OPERATIONS
B21: Parametro / Parameter | C21: Valor 2026 | D21: Valor 2027 | E21: Unidade / Unit | F21: Fonte-Nota / Source-Note
B22: Rotas arranque (Sem1) / Launch routes (W1) | C22: 5 | D22: 5 | E22: rotas/dia | F22: Amazon PT DSP Guide
B23: Rotas regime / Steady-state routes | C23: 25 | D23: 25 | E23: rotas/dia | F23: Amazon PT DSP Guide - base permanente | J23: Analisar melhor algumas assumptions
B24: Rotas pico / Peak routes (Nov-Dez) | C24: 50 | D24: 50 | E24: rotas/dia | F24: Amazon PT DSP Guide
B25: Dias operacionais/semana / Op. days per week | C25: 5 | D25: 5 | E25: dias | F25: Seg-Sab / Mon-Sat
B26: Dias operacionais/mes / Op. days per month | C26: 22 | D26: 22 | E26: dias | F26: Media / Average
B28: C. FROTA E CAPEX / FLEET & CAPEX
B29: Parametro / Parameter | C29: Valor 2026 | D29: Valor 2027 | E29: Unidade / Unit | F29: Fonte-Nota / Source-Note
B30: Frota propria / Own fleet (regime) | C30: 25 | D30: 25 | E30: vans | F30: rotas regime
B31: Buffer de frota / Fleet buffer % | C31: 0.15 | D31: 0.15 | E31: % | F31: Carrinhas de reserva p/ avarias/manutencao/inspecoes (15%)
B32: Leasing por van/mes / Lease per van/month | C32: 800 | D32: 800 | E32: €/van | F32: Est. 36m (contrato fixo)
B33: Seguro por van/mes / Insurance per van/month | C33: 120 | D33: 125 | E33: €/van | F33: Apolice frota (2027: +)
B34: Manutencao por van/mes / Maintenance per van/month | C34: 150 | D34: 160 | E34: €/van | F34: Padrao (2027: vans + velhas)
B35: Aluguer pico por van/mes / Peak rental per van/month | C35: 1400 | D35: 1450 | E35: €/van | F35: Aluguer 3m
B36: Reserva dispositivos / Device reserve | C36: 100 | D36: 100 | E36: €/mes | F36: Contrato Amazon
B38: D. MAO-DE-OBRA / LABOUR
B39: Parametro / Parameter | C39: Valor 2026 | D39: Valor 2027 | E39: Unidade / Unit | F39: Fonte-Nota / Source-Note
B40: Salario DA por hora (bruto) / DA hourly wage (gross) | C40: 6.2 | D40: 6.2 | E40: €/h | F40: Acima do minimo (€5,88/h); compromisso competitividade/rentabilidade
B41: Salario DA mensal (=hora x 2080/12) / DA monthly wage | C41: =C40*2080/12 -> 1074.6667 | D41: =D40*2080/12 -> 1074.6667 | E41: €/mes | F41: Calculado: hora x 2080h/ano / 12 meses (metodo PT)
B42: Taxa SS patronal / Employer SS rate | C42: 0.2375 | D42: 0.2375 | E42: % | F42: Seg. Social PT - 23.75%
B43: Custo total DA c/SS / DA total cost incl. SS | C43: =C41*(1+C42) -> 1329.9 | D43: =D41*(1+D42) -> 1329.9 | E43: €/mes | F43: Calculado
B44: Salario gestor por hora (bruto) / Manager hourly wage | C44: 11.5 | D44: 11.85 | E44: €/h | F44: Gestor de operacoes c/ CAM - acima do motorista (2027: +~3%)
...

Sheet Operacao_Operations
B1: OPERACAO - ROTAS E VOLUMES / OPERATIONS - ROUTES & VOLUMES
C2: ANO 2026 / YEAR 2026 (Ago-Dez/Aug-Dec) | M2: ANO 2027 / YEAR 2027
B3: Rubrica / Item | C3: S1 Set/Sep 26 | D3: S2 Set/Sep 26 | E3: S3 Set/Sep 26 | F3: S4 Set/Sep 26 | G3: S5 Out/Oct 26 | H3: S6 Out/Oct 26 | I3: S7 Out/Oct 26 | J3: S8 Out/Oct 26 | K3: Nov Nov 26 (Pico/Peak) | L3: Dez Dez/Dec 26 (Pico/Peak) | M3: Q1'27 Jan-Mar 27 | N3: Q2'27 Abr-Jun/Apr-Jun 27 | O3: Q3'27 Jul-Set/Jul-Sep 27 | P3: Out'27 Out/Oct 27 | Q3: Nov'27 Nov 27 (Pico/Peak) | R3: Dez'27 Dez/Dec 27 (Pico/Peak) | S3: Total 2026 | T3: Total 2027
B4: Dias operacionais / Operating days | C4: =Pressupostos_Assumpt!C97 -> 5 | D4: =Pressupostos_Assumpt!D97 -> 5 | E4: =Pressupostos_Assumpt!E97 -> 5 | F4: =Pressupostos_Assumpt!F97 -> 5 | G4: =Pressupostos_Assumpt!G97 -> 5 | H4: =Pressupostos_Assumpt!H97 -> 5 | I4: =Pressupostos_Assumpt!I97 -> 5 | J4: =Pressupostos_Assumpt!J97 -> 5 | ... R4: =Pressupostos_Assumpt!R97 -> 22 | S4: =C4+D4+E4+F4+G4+H4+I4+J4+K4+L4 -> 84 | T4: =M4+N4+O4+P4+Q4+R4 -> 264
B5: Periodos-mes (dias/26) / Period-months | C5: =C4/Pressupostos_Assumpt!C26 -> 0.22727273 | D5: =D4/Pressupostos_Assumpt!C26 -> 0.22727273 | E5: =E4/Pressupostos_Assumpt!C26 -> 0.22727273 | F5: =F4/Pressupostos_Assumpt!C26 -> 0.22727273 | G5: =G4/Pressupostos_Assumpt!C26 -> 0.22727273 | H5: =H4/Pressupostos_Assumpt!C26 -> 0.22727273 | I5: =I4/Pressupostos_Assumpt!C26 -> 0.22727273 | J5: =J4/Pressupostos_Assumpt!C26 -> 0.22727273 | K5: =K4/Pressupostos_Assumpt!C26 -> 1 | L5: =L4/Pressupostos_Assumpt!C26 -> 1 | M5: =M4/Pressupostos_Assumpt!D26 -> 3 | N5: =N4/Pressupostos_Assumpt!D26 -> 3 | O5: =O4/Pressupostos_Assumpt!D26 -> 3 | P5: =P4/Pressupostos_Assumpt!D26 -> 1 | Q5: =Q4/Pressupostos_Assumpt!D26 -> 1 | R5: =R4/Pressupostos_Assumpt!D26 -> 1
B6: Rotas/dia (plano) / Routes/day (plan) | C6: =Pressupostos_Assumpt!C98 -> 5 | D6: =Pressupostos_Assumpt!D98 -> 8 | E6: =Pressupostos_Assumpt!E98 -> 12 | F6: =Pressupostos_Assumpt!F98 -> 16 | G6: =Pressupostos_Assumpt!G98 -> 20 | H6: =Pressupostos_Assumpt!H98 -> 23 | I6: =Pressupostos_Assumpt!I98 -> 25 | J6: =Pressupostos_Assumpt!J98 -> 25 | ... R6: =Pressupostos_Assumpt!R98 -> 50
B7: Rotas-dia totais / Total route-days | C7: =C6*C4 -> 25 | D7: =D6*D4 -> 40 | E7: =E6*E4 -> 60 | F7: =F6*F4 -> 80 | G7: =G6*G4 -> 100 | H7: =H6*H4 -> 115 | I7: =I6*I4 -> 125 | J7: =J6*J4 -> 125 | ... R7: =R6*R4 -> 1100 | S7: =C7+D7+E7+F7+G7+H7+I7+J7+K7+L7 -> 2870 | T7: =M7+N7+O7+P7+Q7+R7 -> 7700
B8: Indice volume / Volume index | C8: =Pressupostos_Assumpt!C99 -> 1 | D8: =Pressupostos_Assumpt!D99 -> 1 | E8: =Pressupostos_Assumpt!E99 -> 1 | F8: =Pressupostos_Assumpt!F99 -> 1 | G8: =Pressupostos_Assumpt!G99 -> 1 | H8: =Pressupostos_Assumpt!H99 -> 1 | I8: =Pressupostos_Assumpt!I99 -> 1 | J8: =Pressupostos_Assumpt!J99 -> 1 | ... R8: =Pressupostos_Assumpt!R99 -> 1.1
B9: Encomendas/rota / Packages per route | C9: =Pressupostos_Assumpt!C12 -> 86 | D9: =Pressupostos_Assumpt!C12 -> 86 | E9: =Pressupostos_Assumpt!C12 -> 86 | F9: =Pressupostos_Assumpt!C12 -> 86 | G9: =Pressupostos_Assumpt!C12 -> 86 | H9: =Pressupostos_Assumpt!C12 -> 86 | I9: =Pressupostos_Assumpt!C12 -> 86 | J9: =Pressupostos_Assumpt!C12 -> 86 | K9: =Pressupostos_Assumpt!C12 -> 86 | L9: =Pressupostos_Assumpt!C12 -> 86 | M9: =Pressupostos_Assumpt!D12 -> 86 | N9: =Pressupostos_Assumpt!D12 -> 86 | O9: =Pressupostos_Assumpt!D12 -> 86 | P9: =Pressupostos_Assumpt!D12 -> 86 | Q9: =Pressupostos_Assumpt!D12 -> 86 | R9: =Pressupostos_Assumpt!D12 -> 86
B10: Encomendas totais / Total packages | C10: =C7*C9*C8 -> 2150 | D10: =D7*D9*D8 -> 3440 | E10: =E7*E9*E8 -> 5160 | F10: =F7*F9*F8 -> 6880 | G10: =G7*G9*G8 -> 8600 | H10: =H7*H9*H8 -> 9890 | I10: =I7*I9*I8 -> 10750 | J10: =J7*J9*J8 -> 10750 | ... R10: =R7*R9*R8 -> 104060 | S10: =C10+D10+E10+F10+G10+H10+I10+J10+K10+L10 -> 256280 | T10: =M10+N10+O10+P10+Q10+R10 -> 683485
B11: CARRINHAS DISPONIVEIS / VANS AVAILABLE
B12: Carrinhas proprias (leasing) / Own vans (leasing) | C12: =CEILING(MIN(C6,Pressupostos_Assumpt!C23)*(1+Pressupostos_Assumpt!C31),1) -> 6 | D12: =CEILING(MIN(D6,Pressupostos_Assumpt!C23)*(1+Pressupostos_Assumpt!C31),1) -> 10 | E12: =CEILING(MIN(E6,Pressupostos_Assumpt!C23)*(1+Pressupostos_Assumpt!C31),1) -> 14 | F12: =CEILING(MIN(F6,Pressupostos_Assumpt!C23)*(1+Pressupostos_Assumpt!C31),1) -> 19 | G12: =CEILING(MIN(G6,Pressupostos_Assumpt!C23)*(1+Pressupostos_Assumpt!C31),1) -> 23 | H12: =CEILING(MIN(H6,Pressupostos_Assumpt!C23)*(1+Pressupostos_Assumpt!C31),1) -> 27 | I12: =CEILING(MIN(I6,Pressupostos_Assumpt!C23)*(1+Pressupostos_Assumpt!C31),1) -> 29 | J12: =CEILING(MIN(J6,Pressupostos_Assumpt!C23)*(1+Pressupostos_Assumpt!C31),1) -> 29 | K12: =CEILING(MIN(K6,Pressupostos_Assumpt!C23)*(1+Pressupostos_Assumpt!C31),1) -> 29 | L12: =CEILING(MIN(L6,Pressupostos_Assumpt!C23)*(1+Pressupostos_Assumpt!C31),1) -> 29 | M12: =CEILING(MIN(M6,Pressupostos_Assumpt!D23)*(1+Pressupostos_Assumpt!D31),1) -> 29 | N12: =CEILING(MIN(N6,Pressupostos_Assumpt!D23)*(1+Pressupostos_Assumpt!D31),1) -> 29 | O12: =CEILING(MIN(O6,Pressupostos_Assumpt!D23)*(1+Pressupostos_Assumpt!D31),1) -> 29 | P12: =CEILING(MIN(P6,Pressupostos_Assumpt!D23)*(1+Pressupostos_Assumpt!D31),1) -> 29 | Q12: =CEILING(MIN(Q6,Pressupostos_Assumpt!D23)*(1+Pressupostos_Assumpt!D31),1) -> 29 | R12: =CEILING(MIN(R6,Pressupostos_Assumpt!D23)*(1+Pressupostos_Assumpt!D31),1) -> 29 | S12: =MAX(C12:L12) -> 29 | T12: =MAX(M12:R12) -> 29
B13: Carrinhas aluguer pico / Peak rental vans | C13: =CEILING(MAX(0,C6-Pressupostos_Assumpt!C23)*(1+Pressupostos_Assumpt!C31),1) -> 0 | D13: =CEILING(MAX(0,D6-Pressupostos_Assumpt!C23)*(1+Pressupostos_Assumpt!C31),1) -> 0 | E13: =CEILING(MAX(0,E6-Pressupostos_Assumpt!C23)*(1+Pressupostos_Assumpt!C31),1) -> 0 | F13: =CEILING(MAX(0,F6-Pressupostos_Assumpt!C23)*(1+Pressupostos_Assumpt!C31),1) -> 0 | G13: =CEILING(MAX(0,G6-Pressupostos_Assumpt!C23)*(1+Pressupostos_Assumpt!C31),1) -> 0 | H13: =CEILING(MAX(0,H6-Pressupostos_Assumpt!C23)*(1+Pressupostos_Assumpt!C31),1) -> 0 | I13: =CEILING(MAX(0,I6-Pressupostos_Assumpt!C23)*(1+Pressupostos_Assumpt!C31),1) -> 0 | J13: =CEILING(MAX(0,J6-Pressupostos_Assumpt!C23)*(1+Pressupostos_Assumpt!C31),1) -> 0 | K13: =CEILING(MAX(0,K6-Pressupostos_Assumpt!C23)*(1+Pressupostos_Assumpt!C31),1) -> 29 | L13: =CEILING(MAX(0,L6-Pressupostos_Assumpt!C23)*(1+Pressupostos_Assumpt!C31),1) -> 29 | M13: =CEILING(MAX(0,M6-Pressupostos_Assumpt!D23)*(1+Pressupostos_Assumpt!D31),1) -> 0 | N13: =CEILING(MAX(0,N6-Pressupostos_Assumpt!D23)*(1+Pressupostos_Assumpt!D31),1) -> 0 | O13: =CEILING(MAX(0,O6-Pressupostos_Assumpt!D23)*(1+Pressupostos_Assumpt!D31),1) -> 0 | P13: =CEILING(MAX(0,P6-Pressupostos_Assumpt!D23)*(1+Pressupostos_Assumpt!D31),1) -> 0 | Q13: =CEILING(MAX(0,Q6-Pressupostos_Assumpt!D23)*(1+Pressupostos_Assumpt!D31),1) -> 29 | R13: =CEILING(MAX(0,R6-Pressupostos_Assumpt!D23)*(1+Pressupostos_Assumpt!D31),1) -> 29 | S13: =MAX(C13:L13) -> 29 | T13: =MAX(M13:R13) -> 29
B14: TOTAL CARRINHAS DISPONIVEIS / TOTAL VANS | C14: =C12+C13 -> 6 | D14: =D12+D13 -> 10 | E14: =E12+E13 -> 14 | F14: =F12+F13 -> 19 | G14: =G12+G13 -> 23 | H14: =H12+H13 -> 27 | I14: =I12+I13 -> 29 | J14: =J12+J13 -> 29 | ... R14: =R12+R13 -> 58 | S14: =MAX(C14:L14) -> 58 | T14: =MAX(M14:R14) -> 58
B15: MOTORISTAS DISPONIVEIS / DRIVERS AVAILABLE
B16: Motoristas permanentes / Permanent drivers | C16: =CEILING(MIN(C6,Pressupostos_Assumpt!C23)*(1+Pressupostos_Assumpt!C49),1) -> 6 | D16: =CEILING(MIN(D6,Pressupostos_Assumpt!C23)*(1+Pressupostos_Assumpt!C49),1) -> 10 | E16: =CEILING(MIN(E6,Pressupostos_Assumpt!C23)*(1+Pressupostos_Assumpt!C49),1) -> 14 | F16: =CEILING(MIN(F6,Pressupostos_Assumpt!C23)*(1+Pressupostos_Assumpt!C49),1) -> 19 | G16: =CEILING(MIN(G6,Pressupostos_Assumpt!C23)*(1+Pressupostos_Assumpt!C49),1) -> 23 | H16: =CEILING(MIN(H6,Pressupostos_Assumpt!C23)*(1+Pressupostos_Assumpt!C49),1) -> 27 | I16: =CEILING(MIN(I6,Pressupostos_Assumpt!C23)*(1+Pressupostos_Assumpt!C49),1) -> 29 | J16: =CEILING(MIN(J6,Pressupostos_Assumpt!C23)*(1+Pressupostos_Assumpt!C49),1) -> 29 | K16: =CEILING(MIN(K6,Pressupostos_Assumpt!C23)*(1+Pressupostos_Assumpt!C49),1) -> 29 | L16: =CEILING(MIN(L6,Pressupostos_Assumpt!C23)*(1+Pressupostos_Assumpt!C49),1) -> 29 | M16: =CEILING(MIN(M6,Pressupostos_Assumpt!D23)*(1+Pressupostos_Assumpt!D49),1) -> 29 | N16: =CEILING(MIN(N6,Pressupostos_Assumpt!D23)*(1+Pressupostos_Assumpt!D49),1) -> 29 | O16: =CEILING(MIN(O6,Pressupostos_Assumpt!D23)*(1+Pressupostos_Assumpt!D49),1) -> 29 | P16: =CEILING(MIN(P6,Pressupostos_Assumpt!D23)*(1+Pressupostos_Assumpt!D49),1) -> 29 | Q16: =CEILING(MIN(Q6,Pressupostos_Assumpt!D23)*(1+Pressupostos_Assumpt!D49),1) -> 29 | R16: =CEILING(MIN(R6,Pressupostos_Assumpt!D23)*(1+Pressupostos_Assumpt!D49),1) -> 29 | S16: =MAX(C16:L16) -> 29 | T16: =MAX(M16:R16) -> 29
B17: Motoristas temporarios ETT / Temp agency drivers | C17: =CEILING(MAX(0,C6-Pressupostos_Assumpt!C23)*(1+Pressupostos_Assumpt!C49),1) -> 0 | D17: =CEILING(MAX(0,D6-Pressupostos_Assumpt!C23)*(1+Pressupostos_Assumpt!C49),1) -> 0 | E17: =CEILING(MAX(0,E6-Pressupostos_Assumpt!C23)*(1+Pressupostos_Assumpt!C49),1) -> 0 | F17: =CEILING(MAX(0,F6-Pressupostos_Assumpt!C23)*(1+Pressupostos_Assumpt!C49),1) -> 0 | G17: =CEILING(MAX(0,G6-Pressupostos_Assumpt!C23)*(1+Pressupostos_Assumpt!C49),1) -> 0 | H17: =CEILING(MAX(0,H6-Pressupostos_Assumpt!C23)*(1+Pressupostos_Assumpt!C49),1) -> 0 | I17: =CEILING(MAX(0,I6-Pressupostos_Assumpt!C23)*(1+Pressupostos_Assumpt!C49),1) -> 0 | J17: =CEILING(MAX(0,J6-Pressupostos_Assumpt!C23)*(1+Pressupostos_Assumpt!C49),1) -> 0 | K17: =CEILING(MAX(0,K6-Pressupostos_Assumpt!C23)*(1+Pressupostos_Assumpt!C49),1) -> 29 | L17: =CEILING(MAX(0,L6-Pressupostos_Assumpt!C23)*(1+Pressupostos_Assumpt!C49),1) -> 29 | M17: =CEILING(MAX(0,M6-Pressupostos_Assumpt!D23)*(1+Pressupostos_Assumpt!D49),1) -> 0 | N17: =CEILING(MAX(0,N6-Pressupostos_Assumpt!D23)*(1+Pressupostos_Assumpt!D49),1) -> 0 | O17: =CEILING(MAX(0,O6-Pressupostos_Assumpt!D23)*(1+Pressupostos_Assumpt!D49),1) -> 0 | P17: =CEILING(MAX(0,P6-Pressupostos_Assumpt!D23)*(1+Pressupostos_Assumpt!D49),1) -> 0 | Q17: =CEILING(MAX(0,Q6-Pressupostos_Assumpt!D23)*(1+Pressupostos_Assumpt!D49),1) -> 29 | R17: =CEILING(MAX(0,R6-Pressupostos_Assumpt!D23)*(1+Pressupostos_Assumpt!D49),1) -> 29 | S17: =MAX(C17:L17) -> 29 | T17: =MAX(M17:R17) -> 29
B18: TOTAL MOTORISTAS DISPONIVEIS / TOTAL DRIVERS | C18: =C16+C17 -> 6 | D18: =D16+D17 -> 10 | E18: =E16+E17 -> 14 | F18: =F16+F17 -> 19 | G18: =G16+G17 -> 23 | H18: =H16+H17 -> 27 | I18: =I16+I17 -> 29 | J18: =J16+J17 -> 29 | ... R18: =R16+R17 -> 58 | S18: =MAX(C18:L18) -> 58 | T18: =MAX(M18:R18) -> 58
B21: RESUMO MENSAL / MONTHLY BREAKDOWN
C22: 2026 (Set-Dez) | G22: 2027
B23: POR MES / BY MONTH | C23: Set/Sep 26 | D23: Out/Oct 26 | E23: Nov 26 | F23: Dez/Dec 26 | G23: Jan 27 | H23: Fev/Feb 27 | I23: Mar 27 | J23: Abr/Apr 27 | K23: Mai/May 27 | L23: Jun 27 | M23: Jul 27 | N23: Ago/Aug 27 | O23: Set/Sep 27 | P23: Out/Oct 27 | Q23: Nov 27 | R23: Dez/Dec 27
B24: Rotas-dia totais / Total route-days | C24: =C7+D7+E7+F7 -> 205 | D24: =G7+H7+I7+J7 -> 465 | E24: =K7 -> 1100 | F24: =L7 -> 1100 | G24: =(M7)/3 -> 550 | H24: =(M7)/3 -> 550 | I24: =(M7)/3 -> 550 | J24: =(N7)/3 -> 550 | K24: =(N7)/3 -> 550 | L24: =(N7)/3 -> 550 | M24: =(O7)/3 -> 550 | N24: =(O7)/3 -> 550 | O24: =(O7)/3 -> 550 | P24: =P7 -> 550 | Q24: =Q7 -> 1100 | R24: =R7 -> 1100
B25: Encomendas totais / Total packages | C25: =C10+D10+E10+F10 -> 17630 | D25: =G10+H10+I10+J10 -> 39990 | E25: =K10 -> 99330 | F25: =L10 -> 99330 | G25: =(M10)/3 -> 42570 | H25: =(M10)/3 -> 42570 | I25: =(M10)/3 -> 42570 | J25: =(N10)/3 -> 49665 | K25: =(N10)/3 -> 49665 | L25: =(N10)/3 -> 49665 | M25: =(O10)/3 -> 49665 | N25: =(O10)/3 -> 49665 | O25: =(O10)/3 -> 49665 | P25: =P10 -> 49665 | Q25: =Q10 -> 104060 | R25: =R10 -> 104060
B26: Carrinhas proprias (max) / Own vans | C26: =MAX(C12,D12,E12,F12) -> 19 | D26: =MAX(G12,H12,I12,J12) -> 29 | E26: =MAX(K12) -> 29 | F26: =MAX(L12) -> 29 | G26: =MAX(M12) -> 29 | H26: =MAX(M12) -> 29 | I26: =MAX(M12) -> 29 | J26: =MAX(N12) -> 29 | K26: =MAX(N12) -> 29 | L26: =MAX(N12) -> 29 | M26: =MAX(O12) -> 29 | N26: =MAX(O12) -> 29 | O26: =MAX(O12) -> 29 | P26: =MAX(P12) -> 29 | Q26: =MAX(Q12) -> 29 | R26: =MAX(R12) -> 29
B27: Carrinhas aluguer (max) / Rental vans | C27: =MAX(C13,D13,E13,F13) -> 0 | D27: =MAX(G13,H13,I13,J13) -> 0 | E27: =MAX(K13) -> 29 | F27: =MAX(L13) -> 29 | G27: =MAX(M13) -> 0 | H27: =MAX(M13) -> 0 | I27: =MAX(M13) -> 0 | J27: =MAX(N13) -> 0 | K27: =MAX(N13) -> 0 | L27: =MAX(N13) -> 0 | M27: =MAX(O13) -> 0 | N27: =MAX(O13) -> 0 | O27: =MAX(O13) -> 0 | P27: =MAX(P13) -> 0 | Q27: =MAX(Q13) -> 29 | R27: =MAX(R13) -> 29
B28: TOTAL carrinhas (max) / Total vans | C28: =MAX(C14,D14,E14,F14) -> 19 | D28: =MAX(G14,H14,I14,J14) -> 29 | E28: =MAX(K14) -> 58 | F28: =MAX(L14) -> 58 | G28: =MAX(M14) -> 29 | H28: =MAX(M14) -> 29 | I28: =MAX(M14) -> 29 | J28: =MAX(N14) -> 29 | K28: =MAX(N14) -> 29 | L28: =MAX(N14) -> 29 | M28: =MAX(O14) -> 29 | N28: =MAX(O14) -> 29 | O28: =MAX(O14) -> 29 | P28: =MAX(P14) -> 29 | Q28: =MAX(Q14) -> 58 | R28: =MAX(R14) -> 58
B29: Motoristas permanentes (max) / Permanent | C29: =MAX(C16,D16,E16,F16) -> 19 | D29: =MAX(G16,H16,I16,J16) -> 29 | E29: =MAX(K16) -> 29 | F29: =MAX(L16) -> 29 | G29: =MAX(M16) -> 29 | H29: =MAX(M16) -> 29 | I29: =MAX(M16) -> 29 | J29: =MAX(N16) -> 29 | K29: =MAX(N16) -> 29 | L29: =MAX(N16) -> 29 | M29: =MAX(O16) -> 29 | N29: =MAX(O16) -> 29 | O29: =MAX(O16) -> 29 | P29: =MAX(P16) -> 29 | Q29: =MAX(Q16) -> 29 | R29: =MAX(R16) -> 29
B30: Motoristas temp ETT (max) / Temp | C30: =MAX(C17,D17,E17,F17) -> 0 | D30: =MAX(G17,H17,I17,J17) -> 0 | E30: =MAX(K17) -> 29 | F30: =MAX(L17) -> 29 | G30: =MAX(M17) -> 0 | H30: =MAX(M17) -> 0 | I30: =MAX(M17) -> 0 | J30: =MAX(N17) -> 0 | K30: =MAX(N17) -> 0 | L30: =MAX(N17) -> 0 | M30: =MAX(O17) -> 0 | N30: =MAX(O17) -> 0 | O30: =MAX(O17) -> 0 | P30: =MAX(P17) -> 0 | Q30: =MAX(Q17) -> 29 | R30: =MAX(R17) -> 29
B31: TOTAL motoristas (max) / Total drivers | C31: =MAX(C18,D18,E18,F18) -> 19 | D31: =MAX(G18,H18,I18,J18) -> 29 | E31: =MAX(K18) -> 58 | F31: =MAX(L18) -> 58 | G31: =MAX(M18) -> 29 | H31: =MAX(M18) -> 29 | I31: =MAX(M18) -> 29 | J31: =MAX(N18) -> 29 | K31: =MAX(N18) -> 29 | L31: =MAX(N18) -> 29 | M31: =MAX(O18) -> 29 | N31: =MAX(O18) -> 29 | O31: =MAX(O18) -> 29 | P31: =MAX(P18) -> 29 | Q31: =MAX(Q18) -> 58 | R31: =MAX(R18) -> 58
B34: RESUMO TRIMESTRAL / QUARTERLY BREAKDOWN
C35: 2026 | E35: 2027
B36: POR TRIMESTRE / BY QUARTER | C36: Q3 2026 Set/Sep 26 | D36: Q4 2026 Out-Dez/Oct-Dec 26 | E36: Q1 2027 Jan-Mar 27 | F36: Q2 2027 Abr-Jun/Apr-Jun 27 | G36: Q3 2027 Jul-Set/Jul-Sep 27 | H36: Q4 2027 Out-Dez/Oct-Dec 27
B37: Rotas-dia totais / Total route-days | C37: =SUM(C7:F7) -> 205 | D37: =SUM(G7:L7) -> 2665 | E37: =SUM(M7:M7) -> 1650 | F37: =SUM(N7:N7) -> 1650 | G37: =SUM(O7:O7) -> 1650 | H37: =SUM(P7:R7) -> 2750
B38: Encomendas totais / Total packages | C38: =SUM(C10:F10) -> 17630 | D38: =SUM(G10:L10) -> 238650 | E38: =SUM(M10:M10) -> 127710 | F38: =SUM(N10:N10) -> 148995 | G38: =SUM(O10:O10) -> 148995 | H38: =SUM(P10:R10) -> 257785
B39: Carrinhas proprias (max) / Own vans | C39: =MAX(C12:F12) -> 19 | D39: =MAX(G12:L12) -> 29 | E39: =MAX(M12:M12) -> 29 | F39: =MAX(N12:N12) -> 29 | G39: =MAX(O12:O12) -> 29 | H39: =MAX(P12:R12) -> 29
B40: Carrinhas aluguer (max) / Rental vans | C40: =MAX(C13:F13) -> 0 | D40: =MAX(G13:L13) -> 29 | E40: =MAX(M13:M13) -> 0 | F40: =MAX(N13:N13) -> 0 | G40: =MAX(O13:O13) -> 0 | H40: =MAX(P13:R13) -> 29
B41: TOTAL carrinhas (max) / Total vans | C41: =MAX(C14:F14) -> 19 | D41: =MAX(G14:L14) -> 58 | E41: =MAX(M14:M14) -> 29 | F41: =MAX(N14:N14) -> 29 | G41: =MAX(O14:O14) -> 29 | H41: =MAX(P14:R14) -> 58
B42: Motoristas permanentes (max) / Permanent | C42: =MAX(C16:F16) -> 19 | D42: =MAX(G16:L16) -> 29 | E42: =MAX(M16:M16) -> 29 | F42: =MAX(N16:N16) -> 29 | G42: =MAX(O16:O16) -> 29 | H42: =MAX(P16:R16) -> 29
B43: Motoristas temp ETT (max) / Temp | C43: =MAX(C17:F17) -> 0 | D43: =MAX(G17:L17) -> 29 | E43: =MAX(M17:M17) -> 0 | F43: =MAX(N17:N17) -> 0 | G43: =MAX(O17:O17) -> 0 | H43: =MAX(P17:R17) -> 29
B44: TOTAL motoristas (max) / Total drivers | C44: =MAX(C18:F18) -> 19 | D44: =MAX(G18:L18) -> 58 | E44: =MAX(M18:M18) -> 29 | F44: =MAX(N18:N18) -> 29 | G44: =MAX(O18:O18) -> 29 | H44: =MAX(P18:R18) -> 58

Sheet Receita_Revenue
B1: RECEITA / REVENUE
C2: ANO 2026 / YEAR 2026 (Ago-Dez/Aug-Dec) | M2: ANO 2027 / YEAR 2027
B3: Rubrica / Item | C3: S1 Set/Sep 26 | D3: S2 Set/Sep 26 | E3: S3 Set/Sep 26 | F3: S4 Set/Sep 26 | G3: S5 Out/Oct 26 | H3: S6 Out/Oct 26 | I3: S7 Out/Oct 26 | J3: S8 Out/Oct 26 | K3: Nov Nov 26 (Pico/Peak) | L3: Dez Dez/Dec 26 (Pico/Peak) | M3: Q1'27 Jan-Mar 27 | N3: Q2'27 Abr-Jun/Apr-Jun 27 | O3: Q3'27 Jul-Set/Jul-Sep 27 | P3: Out'27 Out/Oct 27 | Q3: Nov'27 Nov 27 (Pico/Peak) | R3: Dez'27 Dez/Dec 27 (Pico/Peak) | S3: Total 2026 | T3: Total 2027
B4: A. Receita rota (taxa base) / Route revenue | C4: =Operacao_Operations!C7*Pressupostos_Assumpt!C8 -> 4027.5 | D4: =Operacao_Operations!D7*Pressupostos_Assumpt!C8 -> 6444 | E4: =Operacao_Operations!E7*Pressupostos_Assumpt!C8 -> 9666 | F4: =Operacao_Operations!F7*Pressupostos_Assumpt!C8 -> 12888 | G4: =Operacao_Operations!G7*Pressupostos_Assumpt!C8 -> 16110 | H4: =Operacao_Operations!H7*Pressupostos_Assumpt!C8 -> 18526.5 | I4: =Operacao_Operations!I7*Pressupostos_Assumpt!C8 -> 20137.5 | J4: =Operacao_Operations!J7*Pressupostos_Assumpt!C8 -> 20137.5 | K4: =Operacao_Operations!K7*Pressupostos_Assumpt!C8 -> 177210 | L4: =Operacao_Operations!L7*Pressupostos_Assumpt!C8 -> 177210 | M4: =Operacao_Operations!M7*Pressupostos_Assumpt!D8 -> 265815 | N4: =Operacao_Operations!N7*Pressupostos_Assumpt!D8 -> 265815 | O4: =Operacao_Operations!O7*Pressupostos_Assumpt!D8 -> 265815 | P4: =Operacao_Operations!P7*Pressupostos_Assumpt!D8 -> 88605 | Q4: =Operacao_Operations!Q7*Pressupostos_Assumpt!D8 -> 177210 | R4: =Operacao_Operations!R7*Pressupostos_Assumpt!D8 -> 177210 | S4: =C4+D4+E4+F4+G4+H4+I4+J4+K4+L4 -> 462357 | T4: =M4+N4+O4+P4+Q4+R4 -> 1240470
B5: B. Receita por peca / PPR | C5: =Operacao_Operations!C10*Pressupostos_Assumpt!C11 -> 172 | D5: =Operacao_Operations!D10*Pressupostos_Assumpt!C11 -> 275.2 | E5: =Operacao_Operations!E10*Pressupostos_Assumpt!C11 -> 412.8 | F5: =Operacao_Operations!F10*Pressupostos_Assumpt!C11 -> 550.4 | G5: =Operacao_Operations!G10*Pressupostos_Assumpt!C11 -> 688 | H5: =Operacao_Operations!H10*Pressupostos_Assumpt!C11 -> 791.2 | I5: =Operacao_Operations!I10*Pressupostos_Assumpt!C11 -> 860 | J5: =Operacao_Operations!J10*Pressupostos_Assumpt!C11 -> 860 | K5: =Operacao_Operations!K10*Pressupostos_Assumpt!C11 -> 7946.4 | L5: =Operacao_Operations!L10*Pressupostos_Assumpt!C11 -> 7946.4 | M5: =Operacao_Operations!M10*Pressupostos_Assumpt!D11 -> 5108.4 | N5: =Operacao_Operations!N10*Pressupostos_Assumpt!D11 -> 5959.8 | O5: =Operacao_Operations!O10*Pressupostos_Assumpt!D11 -> 5959.8 | P5: =Operacao_Operations!P10*Pressupostos_Assumpt!D11 -> 1986.6 | Q5: =Operacao_Operations!Q10*Pressupostos_Assumpt!D11 -> 4162.4 | R5: =Operacao_Operations!R10*Pressupostos_Assumpt!D11 -> 4162.4 | S5: =C5+D5+E5+F5+G5+H5+I5+J5+K5+L5 -> 20502.4 | T5: =M5+N5+O5+P5+Q5+R5 -> 27339.4
B6: C. Reembolso combustivel / Fuel reimb. | C6: =Operacao_Operations!C7*Pressupostos_Assumpt!C16 -> 288.75 | D6: =Operacao_Operations!D7*Pressupostos_Assumpt!C16 -> 462 | E6: =Operacao_Operations!E7*Pressupostos_Assumpt!C16 -> 693 | F6: =Operacao_Operations!F7*Pressupostos_Assumpt!C16 -> 924 | G6: =Operacao_Operations!G7*Pressupostos_Assumpt!C16 -> 1155 | H6: =Operacao_Operations!H7*Pressupostos_Assumpt!C16 -> 1328.25 | I6: =Operacao_Operations!I7*Pressupostos_Assumpt!C16 -> 1443.75 | J6: =Operacao_Operations!J7*Pressupostos_Assumpt!C16 -> 1443.75 | K6: =Operacao_Operations!K7*Pressupostos_Assumpt!C16 -> 12705 | L6: =Operacao_Operations!L7*Pressupostos_Assumpt!C16 -> 12705 | M6: =Operacao_Operations!M7*Pressupostos_Assumpt!D16 -> 19635 | N6: =Operacao_Operations!N7*Pressupostos_Assumpt!D16 -> 19635 | O6: =Operacao_Operations!O7*Pressupostos_Assumpt!D16 -> 19635 | P6: =Operacao_Operations!P7*Pressupostos_Assumpt!D16 -> 6545 | Q6: =Operacao_Operations!Q7*Pressupostos_Assumpt!D16 -> 13090 | R6: =Operacao_Operations!R7*Pressupostos_Assumpt!D16 -> 13090 | S6: =C6+D6+E6+F6+G6+H6+I6+J6+K6+L6 -> 33148.5 | T6: =M6+N6+O6+P6+Q6+R6 -> 91630
B7: D. Reembolso portagens / Tolls reimb. | C7: =Operacao_Operations!C7*Pressupostos_Assumpt!C17 -> 87.5 | D7: =Operacao_Operations!D7*Pressupostos_Assumpt!C17 -> 140 | E7: =Operacao_Operations!E7*Pressupostos_Assumpt!C17 -> 210 | F7: =Operacao_Operations!F7*Pressupostos_Assumpt!C17 -> 280 | G7: =Operacao_Operations!G7*Pressupostos_Assumpt!C17 -> 350 | H7: =Operacao_Operations!H7*Pressupostos_Assumpt!C17 -> 402.5 | I7: =Operacao_Operations!I7*Pressupostos_Assumpt!C17 -> 437.5 | J7: =Operacao_Operations!J7*Pressupostos_Assumpt!C17 -> 437.5 | K7: =Operacao_Operations!K7*Pressupostos_Assumpt!C17 -> 3850 | L7: =Operacao_Operations!L7*Pressupostos_Assumpt!C17 -> 3850 | M7: =Operacao_Operations!M7*Pressupostos_Assumpt!D17 -> 5775 | N7: =Operacao_Operations!N7*Pressupostos_Assumpt!D17 -> 5775 | O7: =Operacao_Operations!O7*Pressupostos_Assumpt!D17 -> 5775 | P7: =Operacao_Operations!P7*Pressupostos_Assumpt!D17 -> 1925 | Q7: =Operacao_Operations!Q7*Pressupostos_Assumpt!D17 -> 3850 | R7: =Operacao_Operations!R7*Pressupostos_Assumpt!D17 -> 3850 | S7: =C7+D7+E7+F7+G7+H7+I7+J7+K7+L7 -> 10045 | T7: =M7+N7+O7+P7+Q7+R7 -> 26950
B8: E. Incentivo SLS / SLS incentive | C8: =Pressupostos_Assumpt!C18*Operacao_Operations!C5 -> 113.63636 | D8: =Pressupostos_Assumpt!C18*Operacao_Operations!D5 -> 113.63636 | E8: =Pressupostos_Assumpt!C18*Operacao_Operations!E5 -> 113.63636 | F8: =Pressupostos_Assumpt!C18*Operacao_Operations!F5 -> 113.63636 | G8: =Pressupostos_Assumpt!C18*Operacao_Operations!G5 -> 113.63636 | H8: =Pressupostos_Assumpt!C18*Operacao_Operations!H5 -> 113.63636 | I8: =Pressupostos_Assumpt!C18*Operacao_Operations!I5 -> 113.63636 | J8: =Pressupostos_Assumpt!C18*Operacao_Operations!J5 -> 113.63636 | K8: =Pressupostos_Assumpt!C18*Operacao_Operations!K5 -> 500 | L8: =Pressupostos_Assumpt!C18*Operacao_Operations!L5 -> 500 | M8: =Pressupostos_Assumpt!D18*Operacao_Operations!M5 -> 1500 | N8: =Pressupostos_Assumpt!D18*Operacao_Operations!N5 -> 1500 | O8: =Pressupostos_Assumpt!D18*Operacao_Operations!O5 -> 1500 | P8: =Pressupostos_Assumpt!D18*Operacao_Operations!P5 -> 500 | Q8: =Pressupostos_Assumpt!D18*Operacao_Operations!Q5 -> 500 | R8: =Pressupostos_Assumpt!D18*Operacao_Operations!R5 -> 500 | S8: =C8+D8+E8+F8+G8+H8+I8+J8+K8+L8 -> 1909.0909 | T8: =M8+N8+O8+P8+Q8+R8 -> 6000
B9: RECEITA TOTAL / TOTAL REVENUE | C9: =SUM(C4:C8) -> 4689.3864 | D9: =SUM(D4:D8) -> 7434.8364 | E9: =SUM(E4:E8) -> 11095.436 | F9: =SUM(F4:F8) -> 14756.036 | G9: =SUM(G4:G8) -> 18416.636 | H9: =SUM(H4:H8) -> 21162.086 | I9: =SUM(I4:I8) -> 22992.386 | J9: =SUM(J4:J8) -> 22992.386 | ... R9: =SUM(R4:R8) -> 198812.4 | S9: =C9+D9+E9+F9+G9+H9+I9+J9+K9+L9 -> 527961.99 | T9: =M9+N9+O9+P9+Q9+R9 -> 1392389.4
B12: RESUMO MENSAL / MONTHLY BREAKDOWN
C13: 2026 (Set-Dez) | G13: 2027
B14: POR MES / BY MONTH | C14: Set/Sep 26 | D14: Out/Oct 26 | E14: Nov 26 | F14: Dez/Dec 26 | G14: Jan 27 | H14: Fev/Feb 27 | I14: Mar 27 | J14: Abr/Apr 27 | K14: Mai/May 27 | L14: Jun 27 | M14: Jul 27 | N14: Ago/Aug 27 | O14: Set/Sep 27 | P14: Out/Oct 27 | Q14: Nov 27 | R14: Dez/Dec 27
B15: A. Receita rota / Route revenue | C15: =C4+D4+E4+F4 -> 33025.5 | D15: =G4+H4+I4+J4 -> 74911.5 | E15: =K4 -> 177210 | F15: =L4 -> 177210 | G15: =(M4)/3 -> 88605 | H15: =(M4)/3 -> 88605 | I15: =(M4)/3 -> 88605 | J15: =(N4)/3 -> 88605 | K15: =(N4)/3 -> 88605 | L15: =(N4)/3 -> 88605 | M15: =(O4)/3 -> 88605 | N15: =(O4)/3 -> 88605 | O15: =(O4)/3 -> 88605 | P15: =P4 -> 88605 | Q15: =Q4 -> 177210 | R15: =R4 -> 177210
B16: B. PPR | C16: =C5+D5+E5+F5 -> 1410.4 | D16: =G5+H5+I5+J5 -> 3199.2 | E16: =K5 -> 7946.4 | F16: =L5 -> 7946.4 | G16: =(M5)/3 -> 1702.8 | H16: =(M5)/3 -> 1702.8 | I16: =(M5)/3 -> 1702.8 | J16: =(N5)/3 -> 1986.6 | K16: =(N5)/3 -> 1986.6 | L16: =(N5)/3 -> 1986.6 | M16: =(O5)/3 -> 1986.6 | N16: =(O5)/3 -> 1986.6 | O16: =(O5)/3 -> 1986.6 | P16: =P5 -> 1986.6 | Q16: =Q5 -> 4162.4 | R16: =R5 -> 4162.4
B17: C. Combustivel / Fuel | C17: =C6+D6+E6+F6 -> 2367.75 | D17: =G6+H6+I6+J6 -> 5370.75 | E17: =K6 -> 12705 | F17: =L6 -> 12705 | G17: =(M6)/3 -> 6545 | H17: =(M6)/3 -> 6545 | I17: =(M6)/3 -> 6545 | J17: =(N6)/3 -> 6545 | K17: =(N6)/3 -> 6545 | L17: =(N6)/3 -> 6545 | M17: =(O6)/3 -> 6545 | N17: =(O6)/3 -> 6545 | O17: =(O6)/3 -> 6545 | P17: =P6 -> 6545 | Q17: =Q6 -> 13090 | R17: =R6 -> 13090
B18: D. Portagens / Tolls | C18: =C7+D7+E7+F7 -> 717.5 | D18: =G7+H7+I7+J7 -> 1627.5 | E18: =K7 -> 3850 | F18: =L7 -> 3850 | G18: =(M7)/3 -> 1925 | H18: =(M7)/3 -> 1925 | I18: =(M7)/3 -> 1925 | J18: =(N7)/3 -> 1925 | K18: =(N7)/3 -> 1925 | L18: =(N7)/3 -> 1925 | M18: =(O7)/3 -> 1925 | N18: =(O7)/3 -> 1925 | O18: =(O7)/3 -> 1925 | P18: =P7 -> 1925 | Q18: =Q7 -> 3850 | R18: =R7 -> 3850
B19: E. SLS | C19: =C8+D8+E8+F8 -> 454.54545 | D19: =G8+H8+I8+J8 -> 454.54545 | E19: =K8 -> 500 | F19: =L8 -> 500 | G19: =(M8)/3 -> 500 | H19: =(M8)/3 -> 500 | I19: =(M8)/3 -> 500 | J19: =(N8)/3 -> 500 | K19: =(N8)/3 -> 500 | L19: =(N8)/3 -> 500 | M19: =(O8)/3 -> 500 | N19: =(O8)/3 -> 500 | O19: =(O8)/3 -> 500 | P19: =P8 -> 500 | Q19: =Q8 -> 500 | R19: =R8 -> 500
B20: RECEITA TOTAL / TOTAL REVENUE | C20: =C9+D9+E9+F9 -> 37975.695 | D20: =G9+H9+I9+J9 -> 85563.495 | E20: =K9 -> 202211.4 | F20: =L9 -> 202211.4 | G20: =(M9)/3 -> 99277.8 | H20: =(M9)/3 -> 99277.8 | I20: =(M9)/3 -> 99277.8 | J20: =(N9)/3 -> 99561.6 | K20: =(N9)/3 -> 99561.6 | L20: =(N9)/3 -> 99561.6 | M20: =(O9)/3 -> 99561.6 | N20: =(O9)/3 -> 99561.6 | O20: =(O9)/3 -> 99561.6 | P20: =P9 -> 99561.6 | Q20: =Q9 -> 198812.4 | R20: =R9 -> 198812.4
B23: RESUMO TRIMESTRAL / QUARTERLY BREAKDOWN
C24: 2026 | E24: 2027
B25: POR TRIMESTRE / BY QUARTER | C25: Q3 2026 Set/Sep 26 | D25: Q4 2026 Out-Dez/Oct-Dec 26 | E25: Q1 2027 Jan-Mar 27 | F25: Q2 2027 Abr-Jun/Apr-Jun 27 | G25: Q3 2027 Jul-Set/Jul-Sep 27 | H25: Q4 2027 Out-Dez/Oct-Dec 27
B26: A. Receita rota / Route revenue | C26: =SUM(C4:F4) -> 33025.5 | D26: =SUM(G4:L4) -> 429331.5 | E26: =SUM(M4:M4) -> 265815 | F26: =SUM(N4:N4) -> 265815 | G26: =SUM(O4:O4) -> 265815 | H26: =SUM(P4:R4) -> 443025
B27: B. PPR | C27: =SUM(C5:F5) -> 1410.4 | D27: =SUM(G5:L5) -> 19092 | E27: =SUM(M5:M5) -> 5108.4 | F27: =SUM(N5:N5) -> 5959.8 | G27: =SUM(O5:O5) -> 5959.8 | H27: =SUM(P5:R5) -> 10311.4
B28: C. Combustivel / Fuel | C28: =SUM(C6:F6) -> 2367.75 | D28: =SUM(G6:L6) -> 30780.75 | E28: =SUM(M6:M6) -> 19635 | F28: =SUM(N6:N6) -> 19635 | G28: =SUM(O6:O6) -> 19635 | H28: =SUM(P6:R6) -> 32725
B29: D. Portagens / Tolls | C29: =SUM(C7:F7) -> 717.5 | D29: =SUM(G7:L7) -> 9327.5 | E29: =SUM(M7:M7) -> 5775 | F29: =SUM(N7:N7) -> 5775 | G29: =SUM(O7:O7) -> 5775 | H29: =SUM(P7:R7) -> 9625
B30: E. SLS | C30: =SUM(C8:F8) -> 454.54545 | D30: =SUM(G8:L8) -> 1454.5455 | E30: =SUM(M8:M8) -> 1500 | F30: =SUM(N8:N8) -> 1500 | G30: =SUM(O8:O8) -> 1500 | H30: =SUM(P8:R8) -> 1500
B31: RECEITA TOTAL / TOTAL REVENUE | C31: =SUM(C9:F9) -> 37975.695 | D31: =SUM(G9:L9) -> 489986.3 | E31: =SUM(M9:M9) -> 297833.4 | F31: =SUM(N9:N9) -> 298684.8 | G31: =SUM(O9:O9) -> 298684.8 | H31: =SUM(P9:R9) -> 497186.4

Sheet Salarios_Wages
B1: SALARIOS, SUBSIDIOS E ENCARGOS / WAGES, ALLOWANCES & CONTRIBUTIONS
B2: Metodologia PT: 14 meses em 12 | Sub.alimentacao isento | SS trab.11% + patronal 23.75% | IRS por funcao | Temporarios via ETT = salario x coef. (agencia trata SS/subsidios/margem). Valores 2026/2027 conforme Pressupostos.
C3: ANO 2026 / YEAR 2026 (Ago-Dez/Aug-Dec) | M3: ANO 2027 / YEAR 2027
B4: Rubrica / Item | C4: S1 Set/Sep 26 | D4: S2 Set/Sep 26 | E4: S3 Set/Sep 26 | F4: S4 Set/Sep 26 | G4: S5 Out/Oct 26 | H4: S6 Out/Oct 26 | I4: S7 Out/Oct 26 | J4: S8 Out/Oct 26 | K4: Nov Nov 26 (Pico/Peak) | L4: Dez Dez/Dec 26 (Pico/Peak) | M4: Q1'27 Jan-Mar 27 | N4: Q2'27 Abr-Jun/Apr-Jun 27 | O4: Q3'27 Jul-Set/Jul-Sep 27 | P4: Out'27 Out/Oct 27 | Q4: Nov'27 Nov 27 (Pico/Peak) | R4: Dez'27 Dez/Dec 27 (Pico/Peak) | S4: Total 2026 | T4: Total 2027
B5: A. MOTORISTAS PERMANENTES / PERMANENT DRIVERS
B6: Nº permanentes / Permanent headcount | C6: =Operacao_Operations!C16 -> 6 | D6: =Operacao_Operations!D16 -> 10 | E6: =Operacao_Operations!E16 -> 14 | F6: =Operacao_Operations!F16 -> 19 | G6: =Operacao_Operations!G16 -> 23 | H6: =Operacao_Operations!H16 -> 27 | I6: =Operacao_Operations!I16 -> 29 | J6: =Operacao_Operations!J16 -> 29 | ... R6: =Operacao_Operations!R16 -> 29
B7: Salario base bruto / Gross base wage | C7: =Operacao_Operations!C16*Pressupostos_Assumpt!C41*Operacao_Operations!C5 -> 1465.4545 | D7: =Operacao_Operations!D16*Pressupostos_Assumpt!C41*Operacao_Operations!D5 -> 2442.4242 | E7: =Operacao_Operations!E16*Pressupostos_Assumpt!C41*Operacao_Operations!E5 -> 3419.3939 | F7: =Operacao_Operations!F16*Pressupostos_Assumpt!C41*Operacao_Operations!F5 -> 4640.6061 | G7: =Operacao_Operations!G16*Pressupostos_Assumpt!C41*Operacao_Operations!G5 -> 5617.5758 | H7: =Operacao_Operations!H16*Pressupostos_Assumpt!C41*Operacao_Operations!H5 -> 6594.5455 | I7: =Operacao_Operations!I16*Pressupostos_Assumpt!C41*Operacao_Operations!I5 -> 7083.0303 | J7: =Operacao_Operations!J16*Pressupostos_Assumpt!C41*Operacao_Operations!J5 -> 7083.0303 | K7: =Operacao_Operations!K16*Pressupostos_Assumpt!C41*Operacao_Operations!K5 -> 31165.333 | L7: =Operacao_Operations!L16*Pressupostos_Assumpt!C41*Operacao_Operations!L5 -> 31165.333 | M7: =Operacao_Operations!M16*Pressupostos_Assumpt!D41*Operacao_Operations!M5 -> 93496 | N7: =Operacao_Operations!N16*Pressupostos_Assumpt!D41*Operacao_Operations!N5 -> 93496 | O7: =Operacao_Operations!O16*Pressupostos_Assumpt!D41*Operacao_Operations!O5 -> 93496 | P7: =Operacao_Operations!P16*Pressupostos_Assumpt!D41*Operacao_Operations!P5 -> 31165.333 | Q7: =Operacao_Operations!Q16*Pressupostos_Assumpt!D41*Operacao_Operations!Q5 -> 31165.333 | R7: =Operacao_Operations!R16*Pressupostos_Assumpt!D41*Operacao_Operations!R5 -> 31165.333 | S7: =C7+D7+E7+F7+G7+H7+I7+J7+K7+L7 -> 100676.73 | T7: =M7+N7+O7+P7+Q7+R7 -> 373984
B8: Subs. Natal+ferias / Christmas+holiday | C8: =Operacao_Operations!C16*Pressupostos_Assumpt!C41*(Pressupostos_Assumpt!C54-1)*Operacao_Operations!C5 -> 244.24242 | D8: =Operacao_Operations!D16*Pressupostos_Assumpt!C41*(Pressupostos_Assumpt!C54-1)*Operacao_Operations!D5 -> 407.07071 | E8: =Operacao_Operations!E16*Pressupostos_Assumpt!C41*(Pressupostos_Assumpt!C54-1)*Operacao_Operations!E5 -> 569.89899 | F8: =Operacao_Operations!F16*Pressupostos_Assumpt!C41*(Pressupostos_Assumpt!C54-1)*Operacao_Operations!F5 -> 773.43434 | G8: =Operacao_Operations!G16*Pressupostos_Assumpt!C41*(Pressupostos_Assumpt!C54-1)*Operacao_Operations!G5 -> 936.26263 | H8: =Operacao_Operations!H16*Pressupostos_Assumpt!C41*(Pressupostos_Assumpt!C54-1)*Operacao_Operations!H5 -> 1099.0909 | I8: =Operacao_Operations!I16*Pressupostos_Assumpt!C41*(Pressupostos_Assumpt!C54-1)*Operacao_Operations!I5 -> 1180.5051 | J8: =Operacao_Operations!J16*Pressupostos_Assumpt!C41*(Pressupostos_Assumpt!C54-1)*Operacao_Operations!J5 -> 1180.5051 | K8: =Operacao_Operations!K16*Pressupostos_Assumpt!C41*(Pressupostos_Assumpt!C54-1)*Operacao_Operations!K5 -> 5194.2222 | L8: =Operacao_Operations!L16*Pressupostos_Assumpt!C41*(Pressupostos_Assumpt!C54-1)*Operacao_Operations!L5 -> 5194.2222 | M8: =Operacao_Operations!M16*Pressupostos_Assumpt!D41*(Pressupostos_Assumpt!D54-1)*Operacao_Operations!M5 -> 15582.667 | N8: =Operacao_Operations!N16*Pressupostos_Assumpt!D41*(Pressupostos_Assumpt!D54-1)*Operacao_Operations!N5 -> 15582.667 | O8: =Operacao_Operations!O16*Pressupostos_Assumpt!D41*(Pressupostos_Assumpt!D54-1)*Operacao_Operations!O5 -> 15582.667 | P8: =Operacao_Operations!P16*Pressupostos_Assumpt!D41*(Pressupostos_Assumpt!D54-1)*Operacao_Operations!P5 -> 5194.2222 | Q8: =Operacao_Operations!Q16*Pressupostos_Assumpt!D41*(Pressupostos_Assumpt!D54-1)*Operacao_Operations!Q5 -> 5194.2222 | R8: =Operacao_Operations!R16*Pressupostos_Assumpt!D41*(Pressupostos_Assumpt!D54-1)*Operacao_Operations!R5 -> 5194.2222 | S8: =C8+D8+E8+F8+G8+H8+I8+J8+K8+L8 -> 16779.455 | T8: =M8+N8+O8+P8+Q8+R8 -> 62330.667
B9: Subs. alimentacao / Food subsidy | C9: =Operacao_Operations!C16*Pressupostos_Assumpt!C56*Pressupostos_Assumpt!C58*Operacao_Operations!C5 -> 180 | D9: =Operacao_Operations!D16*Pressupostos_Assumpt!C56*Pressupostos_Assumpt!C58*Operacao_Operations!D5 -> 300 | E9: =Operacao_Operations!E16*Pressupostos_Assumpt!C56*Pressupostos_Assumpt!C58*Operacao_Operations!E5 -> 420 | F9: =Operacao_Operations!F16*Pressupostos_Assumpt!C56*Pressupostos_Assumpt!C58*Operacao_Operations!F5 -> 570 | G9: =Operacao_Operations!G16*Pressupostos_Assumpt!C56*Pressupostos_Assumpt!C58*Operacao_Operations!G5 -> 690 | H9: =Operacao_Operations!H16*Pressupostos_Assumpt!C56*Pressupostos_Assumpt!C58*Operacao_Operations!H5 -> 810 | I9: =Operacao_Operations!I16*Pressupostos_Assumpt!C56*Pressupostos_Assumpt!C58*Operacao_Operations!I5 -> 870 | J9: =Operacao_Operations!J16*Pressupostos_Assumpt!C56*Pressupostos_Assumpt!C58*Operacao_Operations!J5 -> 870 | K9: =Operacao_Operations!K16*Pressupostos_Assumpt!C56*Pressupostos_Assumpt!C58*Operacao_Operations!K5 -> 3828 | L9: =Operacao_Operations!L16*Pressupostos_Assumpt!C56*Pressupostos_Assumpt!C58*Operacao_Operations!L5 -> 3828 | M9: =Operacao_Operations!M16*Pressupostos_Assumpt!D56*Pressupostos_Assumpt!D58*Operacao_Operations!M5 -> 11484 | N9: =Operacao_Operations!N16*Pressupostos_Assumpt!D56*Pressupostos_Assumpt!D58*Operacao_Operations!N5 -> 11484 | O9: =Operacao_Operations!O16*Pressupostos_Assumpt!D56*Pressupostos_Assumpt!D58*Operacao_Operations!O5 -> 11484 | P9: =Operacao_Operations!P16*Pressupostos_Assumpt!D56*Pressupostos_Assumpt!D58*Operacao_Operations!P5 -> 3828 | Q9: =Operacao_Operations!Q16*Pressupostos_Assumpt!D56*Pressupostos_Assumpt!D58*Operacao_Operations!Q5 -> 3828 | R9: =Operacao_Operations!R16*Pressupostos_Assumpt!D56*Pressupostos_Assumpt!D58*Operacao_Operations!R5 -> 3828 | S9: =C9+D9+E9+F9+G9+H9+I9+J9+K9+L9 -> 12366 | T9: =M9+N9+O9+P9+Q9+R9 -> 45936
B10: Remuneracao bruta total / Total gross | C10: =C7+C8+C9 -> 1889.697 | D10: =D7+D8+D9 -> 3149.4949 | E10: =E7+E8+E9 -> 4409.2929 | F10: =F7+F8+F9 -> 5984.0404 | G10: =G7+G8+G9 -> 7243.8384 | H10: =H7+H8+H9 -> 8503.6364 | I10: =I7+I8+I9 -> 9133.5354 | J10: =J7+J8+J9 -> 9133.5354 | ... R10: =R7+R8+R9 -> 40187.556 | S10: =C10+D10+E10+F10+G10+H10+I10+J10+K10+L10 -> 129822.18 | T10: =M10+N10+O10+P10+Q10+R10 -> 482250.67
B11: SS patronal (23.75%) + s/ excesso sub. / Employer SS | C11: =(C7+C8)*Pressupostos_Assumpt!C42+Operacao_Operations!C16*MAX(0,Pressupostos_Assumpt!C56-Pressupostos_Assumpt!C57)*Pressupostos_Assumpt!C58*Pressupostos_Assumpt!C42*Operacao_Operations!C5 -> 406.05303 | D11: =(D7+D8)*Pressupostos_Assumpt!C42+Operacao_Operations!D16*MAX(0,Pressupostos_Assumpt!C56-Pressupostos_Assumpt!C57)*Pressupostos_Assumpt!C58*Pressupostos_Assumpt!C42*Operacao_Operations!D5 -> 676.75505 | E11: =(E7+E8)*Pressupostos_Assumpt!C42+Operacao_Operations!E16*MAX(0,Pressupostos_Assumpt!C56-Pressupostos_Assumpt!C57)*Pressupostos_Assumpt!C58*Pressupostos_Assumpt!C42*Operacao_Operations!E5 -> 947.45707 | F11: =(F7+F8)*Pressupostos_Assumpt!C42+Operacao_Operations!F16*MAX(0,Pressupostos_Assumpt!C56-Pressupostos_Assumpt!C57)*Pressupostos_Assumpt!C58*Pressupostos_Assumpt!C42*Operacao_Operations!F5 -> 1285.8346 | G11: =(G7+G8)*Pressupostos_Assumpt!C42+Operacao_Operations!G16*MAX(0,Pressupostos_Assumpt!C56-Pressupostos_Assumpt!C57)*Pressupostos_Assumpt!C58*Pressupostos_Assumpt!C42*Operacao_Operations!G5 -> 1556.5366 | H11: =(H7+H8)*Pressupostos_Assumpt!C42+Operacao_Operations!H16*MAX(0,Pressupostos_Assumpt!C56-Pressupostos_Assumpt!C57)*Pressupostos_Assumpt!C58*Pressupostos_Assumpt!C42*Operacao_Operations!H5 -> 1827.2386 | I11: =(I7+I8)*Pressupostos_Assumpt!C42+Operacao_Operations!I16*MAX(0,Pressupostos_Assumpt!C56-Pressupostos_Assumpt!C57)*Pressupostos_Assumpt!C58*Pressupostos_Assumpt!C42*Operacao_Operations!I5 -> 1962.5896 | J11: =(J7+J8)*Pressupostos_Assumpt!C42+Operacao_Operations!J16*MAX(0,Pressupostos_Assumpt!C56-Pressupostos_Assumpt!C57)*Pressupostos_Assumpt!C58*Pressupostos_Assumpt!C42*Operacao_Operations!J5 -> 1962.5896 | K11: =(K7+K8)*Pressupostos_Assumpt!C42+Operacao_Operations!K16*MAX(0,Pressupostos_Assumpt!C56-Pressupostos_Assumpt!C57)*Pressupostos_Assumpt!C58*Pressupostos_Assumpt!C42*Operacao_Operations!K5 -> 8635.3944 | L11: =(L7+L8)*Pressupostos_Assumpt!C42+Operacao_Operations!L16*MAX(0,Pressupostos_Assumpt!C56-Pressupostos_Assumpt!C57)*Pressupostos_Assumpt!C58*Pressupostos_Assumpt!C42*Operacao_Operations!L5 -> 8635.3944 | M11: =(M7+M8)*Pressupostos_Assumpt!D42+Operacao_Operations!M16*MAX(0,Pressupostos_Assumpt!D56-Pressupostos_Assumpt!D57)*Pressupostos_Assumpt!D58*Pressupostos_Assumpt!D42*Operacao_Operations!M5 -> 25906.183 | N11: =(N7+N8)*Pressupostos_Assumpt!D42+Operacao_Operations!N16*MAX(0,Pressupostos_Assumpt!D56-Pressupostos_Assumpt!D57)*Pressupostos_Assumpt!D58*Pressupostos_Assumpt!D42*Operacao_Operations!N5 -> 25906.183 | O11: =(O7+O8)*Pressupostos_Assumpt!D42+Operacao_Operations!O16*MAX(0,Pressupostos_Assumpt!D56-Pressupostos_Assumpt!D57)*Pressupostos_Assumpt!D58*Pressupostos_Assumpt!D42*Operacao_Operations!O5 -> 25906.183 | P11: =(P7+P8)*Pressupostos_Assumpt!D42+Operacao_Operations!P16*MAX(0,Pressupostos_Assumpt!D56-Pressupostos_Assumpt!D57)*Pressupostos_Assumpt!D58*Pressupostos_Assumpt!D42*Operacao_Operations!P5 -> 8635.3944 | Q11: =(Q7+Q8)*Pressupostos_Assumpt!D42+Operacao_Operations!Q16*MAX(0,Pressupostos_Assumpt!D56-Pressupostos_Assumpt!D57)*Pressupostos_Assumpt!D58*Pressupostos_Assumpt!D42*Operacao_Operations!Q5 -> 8635.3944 | R11: =(R7+R8)*Pressupostos_Assumpt!D42+Operacao_Operations!R16*MAX(0,Pressupostos_Assumpt!D56-Pressupostos_Assumpt!D57)*Pressupostos_Assumpt!D58*Pressupostos_Assumpt!D42*Operacao_Operations!R5 -> 8635.3944 | S11: =C11+D11+E11+F11+G11+H11+I11+J11+K11+L11 -> 27895.843 | T11: =M11+N11+O11+P11+Q11+R11 -> 103624.73
B12: SS trabalhador (11%) / Employee SS | C12: =(C7+C8)*Pressupostos_Assumpt!C55 -> 188.06667 | D12: =(D7+D8)*Pressupostos_Assumpt!C55 -> 313.44444 | E12: =(E7+E8)*Pressupostos_Assumpt!C55 -> 438.82222 | F12: =(F7+F8)*Pressupostos_Assumpt!C55 -> 595.54444 | G12: =(G7+G8)*Pressupostos_Assumpt!C55 -> 720.92222 | H12: =(H7+H8)*Pressupostos_Assumpt!C55 -> 846.3 | I12: =(I7+I8)*Pressupostos_Assumpt!C55 -> 908.98889 | J12: =(J7+J8)*Pressupostos_Assumpt!C55 -> 908.98889 | K12: =(K7+K8)*Pressupostos_Assumpt!C55 -> 3999.5511 | L12: =(L7+L8)*Pressupostos_Assumpt!C55 -> 3999.5511 | M12: =(M7+M8)*Pressupostos_Assumpt!D55 -> 11998.653 | N12: =(N7+N8)*Pressupostos_Assumpt!D55 -> 11998.653 | O12: =(O7+O8)*Pressupostos_Assumpt!D55 -> 11998.653 | P12: =(P7+P8)*Pressupostos_Assumpt!D55 -> 3999.5511 | Q12: =(Q7+Q8)*Pressupostos_Assumpt!D55 -> 3999.5511 | R12: =(R7+R8)*Pressupostos_Assumpt!D55 -> 3999.5511 | S12: =C12+D12+E12+F12+G12+H12+I12+J12+K12+L12 -> 12920.18 | T12: =M12+N12+O12+P12+Q12+R12 -> 47994.613
B13: Retencao IRS / IRS withholding | C13: =(C7+C8)*Pressupostos_Assumpt!C59 -> 141.90485 | D13: =(D7+D8)*Pressupostos_Assumpt!C59 -> 236.50808 | E13: =(E7+E8)*Pressupostos_Assumpt!C59 -> 331.11131 | F13: =(F7+F8)*Pressupostos_Assumpt!C59 -> 449.36535 | G13: =(G7+G8)*Pressupostos_Assumpt!C59 -> 543.96859 | H13: =(H7+H8)*Pressupostos_Assumpt!C59 -> 638.57182 | I13: =(I7+I8)*Pressupostos_Assumpt!C59 -> 685.87343 | J13: =(J7+J8)*Pressupostos_Assumpt!C59 -> 685.87343 | K13: =(K7+K8)*Pressupostos_Assumpt!C59 -> 3017.8431 | L13: =(L7+L8)*Pressupostos_Assumpt!C59 -> 3017.8431 | M13: =(M7+M8)*Pressupostos_Assumpt!D59 -> 9053.5293 | N13: =(N7+N8)*Pressupostos_Assumpt!D59 -> 9053.5293 | O13: =(O7+O8)*Pressupostos_Assumpt!D59 -> 9053.5293 | P13: =(P7+P8)*Pressupostos_Assumpt!D59 -> 3017.8431 | Q13: =(Q7+Q8)*Pressupostos_Assumpt!D59 -> 3017.8431 | R13: =(R7+R8)*Pressupostos_Assumpt!D59 -> 3017.8431 | S13: =C13+D13+E13+F13+G13+H13+I13+J13+K13+L13 -> 9748.8631 | T13: =M13+N13+O13+P13+Q13+R13 -> 36214.117
B14: Salario liquido / Net wage | C14: =C7+C8+C9-C12-C13 -> 1559.7255 | D14: =D7+D8+D9-D12-D13 -> 2599.5424 | E14: =E7+E8+E9-E12-E13 -> 3639.3594 | F14: =F7+F8+F9-F12-F13 -> 4939.1306 | G14: =G7+G8+G9-G12-G13 -> 5978.9476 | H14: =H7+H8+H9-H12-H13 -> 7018.7645 | I14: =I7+I8+I9-I12-I13 -> 7538.673 | J14: =J7+J8+J9-J12-J13 -> 7538.673 | ... R14: =R7+R8+R9-R12-R13 -> 33170.161 | S14: =C14+D14+E14+F14+G14+H14+I14+J14+K14+L14 -> 107153.14 | T14: =M14+N14+O14+P14+Q14+R14 -> 398041.94
B15: CUSTO EMPRESA Permanentes / TOTAL PERMANENT COST | C15: =C10+C11 -> 2295.75 | D15: =D10+D11 -> 3826.25 | E15: =E10+E11 -> 5356.75 | F15: =F10+F11 -> 7269.875 | G15: =G10+G11 -> 8800.375 | H15: =H10+H11 -> 10330.875 | I15: =I10+I11 -> 11096.125 | J15: =J10+J11 -> 11096.125 | ... R15: =R10+R11 -> 48822.95 | S15: =C15+D15+E15+F15+G15+H15+I15+J15+K15+L15 -> 157718.03 | T15: =M15+N15+O15+P15+Q15+R15 -> 585875.4
B17: B. MOTORISTAS TEMPORARIOS - ETT / TEMPORARY AGENCY DRIVERS
B18: Nº temporarios / Temp headcount | C18: =Operacao_Operations!C17 -> 0 | D18: =Operacao_Operations!D17 -> 0 | E18: =Operacao_Operations!E17 -> 0 | F18: =Operacao_Operations!F17 -> 0 | G18: =Operacao_Operations!G17 -> 0 | H18: =Operacao_Operations!H17 -> 0 | I18: =Operacao_Operations!I17 -> 0 | J18: =Operacao_Operations!J17 -> 0 | ... R18: =Operacao_Operations!R17 -> 29
B19: Custo faturado base (salario x meses) / Billed base | C19: =Operacao_Operations!C17*Pressupostos_Assumpt!C41*Operacao_Operations!C5 -> 0 | D19: =Operacao_Operations!D17*Pressupostos_Assumpt!C41*Operacao_Operations!D5 -> 0 | E19: =Operacao_Operations!E17*Pressupostos_Assumpt!C41*Operacao_Operations!E5 -> 0 | F19: =Operacao_Operations!F17*Pressupostos_Assumpt!C41*Operacao_Operations!F5 -> 0 | G19: =Operacao_Operations!G17*Pressupostos_Assumpt!C41*Operacao_Operations!G5 -> 0 | H19: =Operacao_Operations!H17*Pressupostos_Assumpt!C41*Operacao_Operations!H5 -> 0 | I19: =Operacao_Operations!I17*Pressupostos_Assumpt!C41*Operacao_Operations!I5 -> 0 | J19: =Operacao_Operations!J17*Pressupostos_Assumpt!C41*Operacao_Operations!J5 -> 0 | K19: =Operacao_Operations!K17*Pressupostos_Assumpt!C41*Operacao_Operations!K5 -> 31165.333 | L19: =Operacao_Operations!L17*Pressupostos_Assumpt!C41*Operacao_Operations!L5 -> 31165.333 | M19: =Operacao_Operations!M17*Pressupostos_Assumpt!D41*Operacao_Operations!M5 -> 0 | N19: =Operacao_Operations!N17*Pressupostos_Assumpt!D41*Operacao_Operations!N5 -> 0 | O19: =Operacao_Operations!O17*Pressupostos_Assumpt!D41*Operacao_Operations!O5 -> 0 | P19: =Operacao_Operations!P17*Pressupostos_Assumpt!D41*Operacao_Operations!P5 -> 0 | Q19: =Operacao_Operations!Q17*Pressupostos_Assumpt!D41*Operacao_Operations!Q5 -> 31165.333 | R19: =Operacao_Operations!R17*Pressupostos_Assumpt!D41*Operacao_Operations!R5 -> 31165.333 | S19: =C19+D19+E19+F19+G19+H19+I19+J19+K19+L19 -> 62330.667 | T19: =M19+N19+O19+P19+Q19+R19 -> 62330.667
B20: CUSTO EMPRESA Temporarios (x coef.) / TOTAL TEMP COST | C20: =C19*Pressupostos_Assumpt!C65 -> 0 | D20: =D19*Pressupostos_Assumpt!C65 -> 0 | E20: =E19*Pressupostos_Assumpt!C65 -> 0 | F20: =F19*Pressupostos_Assumpt!C65 -> 0 | G20: =G19*Pressupostos_Assumpt!C65 -> 0 | H20: =H19*Pressupostos_Assumpt!C65 -> 0 | I20: =I19*Pressupostos_Assumpt!C65 -> 0 | J20: =J19*Pressupostos_Assumpt!C65 -> 0 | K20: =K19*Pressupostos_Assumpt!C65 -> 46748 | L20: =L19*Pressupostos_Assumpt!C65 -> 46748 | M20: =M19*Pressupostos_Assumpt!D65 -> 0 | N20: =N19*Pressupostos_Assumpt!D65 -> 0 | O20: =O19*Pressupostos_Assumpt!D65 -> 0 | P20: =P19*Pressupostos_Assumpt!D65 -> 0 | Q20: =Q19*Pressupostos_Assumpt!D65 -> 46748 | R20: =R19*Pressupostos_Assumpt!D65 -> 46748 | S20: =C20+D20+E20+F20+G20+H20+I20+J20+K20+L20 -> 93496 | T20: =M20+N20+O20+P20+Q20+R20 -> 93496
B22: C. GESTOR DE OPERACOES / OPERATIONS MANAGER
B23: Salario base bruto / Gross base wage | C23: =Pressupostos_Assumpt!C61*Pressupostos_Assumpt!C45*Operacao_Operations!C5 -> 453.0303 | D23: =Pressupostos_Assumpt!C61*Pressupostos_Assumpt!C45*Operacao_Operations!D5 -> 453.0303 | E23: =Pressupostos_Assumpt!C61*Pressupostos_Assumpt!C45*Operacao_Operations!E5 -> 453.0303 | F23: =Pressupostos_Assumpt!C61*Pressupostos_Assumpt!C45*Operacao_Operations!F5 -> 453.0303 | G23: =Pressupostos_Assumpt!C61*Pressupostos_Assumpt!C45*Operacao_Operations!G5 -> 453.0303 | H23: =Pressupostos_Assumpt!C61*Pressupostos_Assumpt!C45*Operacao_Operations!H5 -> 453.0303 | I23: =Pressupostos_Assumpt!C61*Pressupostos_Assumpt!C45*Operacao_Operations!I5 -> 453.0303 | J23: =Pressupostos_Assumpt!C61*Pressupostos_Assumpt!C45*Operacao_Operations!J5 -> 453.0303 | K23: =Pressupostos_Assumpt!C61*Pressupostos_Assumpt!C45*Operacao_Operations!K5 -> 1993.3333 | L23: =Pressupostos_Assumpt!C61*Pressupostos_Assumpt!C45*Operacao_Operations!L5 -> 1993.3333 | M23: =Pressupostos_Assumpt!D61*Pressupostos_Assumpt!D45*Operacao_Operations!M5 -> 6162 | N23: =Pressupostos_Assumpt!D61*Pressupostos_Assumpt!D45*Operacao_Operations!N5 -> 6162 | O23: =Pressupostos_Assumpt!D61*Pressupostos_Assumpt!D45*Operacao_Operations!O5 -> 6162 | P23: =Pressupostos_Assumpt!D61*Pressupostos_Assumpt!D45*Operacao_Operations!P5 -> 2054 | Q23: =Pressupostos_Assumpt!D61*Pressupostos_Assumpt!D45*Operacao_Operations!Q5 -> 2054 | R23: =Pressupostos_Assumpt!D61*Pressupostos_Assumpt!D45*Operacao_Operations!R5 -> 2054 | S23: =C23+D23+E23+F23+G23+H23+I23+J23+K23+L23 -> 7610.9091 | T23: =M23+N23+O23+P23+Q23+R23 -> 24648
B24: Subs. Natal+ferias / Christmas+holiday | C24: =Pressupostos_Assumpt!C61*Pressupostos_Assumpt!C45*(Pressupostos_Assumpt!C54-1)*Operacao_Operations!C5 -> 75.505051 | D24: =Pressupostos_Assumpt!C61*Pressupostos_Assumpt!C45*(Pressupostos_Assumpt!C54-1)*Operacao_Operations!D5 -> 75.505051 | E24: =Pressupostos_Assumpt!C61*Pressupostos_Assumpt!C45*(Pressupostos_Assumpt!C54-1)*Operacao_Operations!E5 -> 75.505051 | F24: =Pressupostos_Assumpt!C61*Pressupostos_Assumpt!C45*(Pressupostos_Assumpt!C54-1)*Operacao_Operations!F5 -> 75.505051 | G24: =Pressupostos_Assumpt!C61*Pressupostos_Assumpt!C45*(Pressupostos_Assumpt!C54-1)*Operacao_Operations!G5 -> 75.505051 | H24: =Pressupostos_Assumpt!C61*Pressupostos_Assumpt!C45*(Pressupostos_Assumpt!C54-1)*Operacao_Operations!H5 -> 75.505051 | I24: =Pressupostos_Assumpt!C61*Pressupostos_Assumpt!C45*(Pressupostos_Assumpt!C54-1)*Operacao_Operations!I5 -> 75.505051 | J24: =Pressupostos_Assumpt!C61*Pressupostos_Assumpt!C45*(Pressupostos_Assumpt!C54-1)*Operacao_Operations!J5 -> 75.505051 | K24: =Pressupostos_Assumpt!C61*Pressupostos_Assumpt!C45*(Pressupostos_Assumpt!C54-1)*Operacao_Operations!K5 -> 332.22222 | L24: =Pressupostos_Assumpt!C61*Pressupostos_Assumpt!C45*(Pressupostos_Assumpt!C54-1)*Operacao_Operations!L5 -> 332.22222 | M24: =Pressupostos_Assumpt!D61*Pressupostos_Assumpt!D45*(Pressupostos_Assumpt!D54-1)*Operacao_Operations!M5 -> 1027 | N24: =Pressupostos_Assumpt!D61*Pressupostos_Assumpt!D45*(Pressupostos_Assumpt!D54-1)*Operacao_Operations!N5 -> 1027 | O24: =Pressupostos_Assumpt!D61*Pressupostos_Assumpt!D45*(Pressupostos_Assumpt!D54-1)*Operacao_Operations!O5 -> 1027 | P24: =Pressupostos_Assumpt!D61*Pressupostos_Assumpt!D45*(Pressupostos_Assumpt!D54-1)*Operacao_Operations!P5 -> 342.33333 | Q24: =Pressupostos_Assumpt!D61*Pressupostos_Assumpt!D45*(Pressupostos_Assumpt!D54-1)*Operacao_Operations!Q5 -> 342.33333 | R24: =Pressupostos_Assumpt!D61*Pressupostos_Assumpt!D45*(Pressupostos_Assumpt!D54-1)*Operacao_Operations!R5 -> 342.33333 | S24: =C24+D24+E24+F24+G24+H24+I24+J24+K24+L24 -> 1268.4848 | T24: =M24+N24+O24+P24+Q24+R24 -> 4108
B25: Subs. alimentacao / Food subsidy | C25: =Pressupostos_Assumpt!C61*Pressupostos_Assumpt!C56*Pressupostos_Assumpt!C58*Operacao_Operations!C5 -> 30 | D25: =Pressupostos_Assumpt!C61*Pressupostos_Assumpt!C56*Pressupostos_Assumpt!C58*Operacao_Operations!D5 -> 30 | E25: =Pressupostos_Assumpt!C61*Pressupostos_Assumpt!C56*Pressupostos_Assumpt!C58*Operacao_Operations!E5 -> 30 | F25: =Pressupostos_Assumpt!C61*Pressupostos_Assumpt!C56*Pressupostos_Assumpt!C58*Operacao_Operations!F5 -> 30 | G25: =Pressupostos_Assumpt!C61*Pressupostos_Assumpt!C56*Pressupostos_Assumpt!C58*Operacao_Operations!G5 -> 30 | H25: =Pressupostos_Assumpt!C61*Pressupostos_Assumpt!C56*Pressupostos_Assumpt!C58*Operacao_Operations!H5 -> 30 | I25: =Pressupostos_Assumpt!C61*Pressupostos_Assumpt!C56*Pressupostos_Assumpt!C58*Operacao_Operations!I5 -> 30 | J25: =Pressupostos_Assumpt!C61*Pressupostos_Assumpt!C56*Pressupostos_Assumpt!C58*Operacao_Operations!J5 -> 30 | K25: =Pressupostos_Assumpt!C61*Pressupostos_Assumpt!C56*Pressupostos_Assumpt!C58*Operacao_Operations!K5 -> 132 | L25: =Pressupostos_Assumpt!C61*Pressupostos_Assumpt!C56*Pressupostos_Assumpt!C58*Operacao_Operations!L5 -> 132 | M25: =Pressupostos_Assumpt!D61*Pressupostos_Assumpt!D56*Pressupostos_Assumpt!D58*Operacao_Operations!M5 -> 396 | N25: =Pressupostos_Assumpt!D61*Pressupostos_Assumpt!D56*Pressupostos_Assumpt!D58*Operacao_Operations!N5 -> 396 | O25: =Pressupostos_Assumpt!D61*Pressupostos_Assumpt!D56*Pressupostos_Assumpt!D58*Operacao_Operations!O5 -> 396 | P25: =Pressupostos_Assumpt!D61*Pressupostos_Assumpt!D56*Pressupostos_Assumpt!D58*Operacao_Operations!P5 -> 132 | Q25: =Pressupostos_Assumpt!D61*Pressupostos_Assumpt!D56*Pressupostos_Assumpt!D58*Operacao_Operations!Q5 -> 132 | R25: =Pressupostos_Assumpt!D61*Pressupostos_Assumpt!D56*Pressupostos_Assumpt!D58*Operacao_Operations!R5 -> 132 | S25: =C25+D25+E25+F25+G25+H25+I25+J25+K25+L25 -> 504 | T25: =M25+N25+O25+P25+Q25+R25 -> 1584
B26: Remuneracao bruta total / Total gross | C26: =C23+C24+C25 -> 558.53535 | D26: =D23+D24+D25 -> 558.53535 | E26: =E23+E24+E25 -> 558.53535 | F26: =F23+F24+F25 -> 558.53535 | G26: =G23+G24+G25 -> 558.53535 | H26: =H23+H24+H25 -> 558.53535 | I26: =I23+I24+I25 -> 558.53535 | J26: =J23+J24+J25 -> 558.53535 | ... R26: =R23+R24+R25 -> 2528.3333 | S26: =C26+D26+E26+F26+G26+H26+I26+J26+K26+L26 -> 9383.3939 | T26: =M26+N26+O26+P26+Q26+R26 -> 30340
B27: SS patronal (23.75%) + s/ excesso sub. / Employer SS | C27: =(C23+C24)*Pressupostos_Assumpt!C42+Pressupostos_Assumpt!C61*MAX(0,Pressupostos_Assumpt!C56-Pressupostos_Assumpt!C57)*Pressupostos_Assumpt!C58*Pressupostos_Assumpt!C42*Operacao_Operations!C5 -> 125.52715 | D27: =(D23+D24)*Pressupostos_Assumpt!C42+Pressupostos_Assumpt!C61*MAX(0,Pressupostos_Assumpt!C56-Pressupostos_Assumpt!C57)*Pressupostos_Assumpt!C58*Pressupostos_Assumpt!C42*Operacao_Operations!D5 -> 125.52715 | E27: =(E23+E24)*Pressupostos_Assumpt!C42+Pressupostos_Assumpt!C61*MAX(0,Pressupostos_Assumpt!C56-Pressupostos_Assumpt!C57)*Pressupostos_Assumpt!C58*Pressupostos_Assumpt!C42*Operacao_Operations!E5 -> 125.52715 | F27: =(F23+F24)*Pressupostos_Assumpt!C42+Pressupostos_Assumpt!C61*MAX(0,Pressupostos_Assumpt!C56-Pressupostos_Assumpt!C57)*Pressupostos_Assumpt!C58*Pressupostos_Assumpt!C42*Operacao_Operations!F5 -> 125.52715 | G27: =(G23+G24)*Pressupostos_Assumpt!C42+Pressupostos_Assumpt!C61*MAX(0,Pressupostos_Assumpt!C56-Pressupostos_Assumpt!C57)*Pressupostos_Assumpt!C58*Pressupostos_Assumpt!C42*Operacao_Operations!G5 -> 125.52715 | H27: =(H23+H24)*Pressupostos_Assumpt!C42+Pressupostos_Assumpt!C61*MAX(0,Pressupostos_Assumpt!C56-Pressupostos_Assumpt!C57)*Pressupostos_Assumpt!C58*Pressupostos_Assumpt!C42*Operacao_Operations!H5 -> 125.52715 | I27: =(I23+I24)*Pressupostos_Assumpt!C42+Pressupostos_Assumpt!C61*MAX(0,Pressupostos_Assumpt!C56-Pressupostos_Assumpt!C57)*Pressupostos_Assumpt!C58*Pressupostos_Assumpt!C42*Operacao_Operations!I5 -> 125.52715 | J27: =(J23+J24)*Pressupostos_Assumpt!C42+Pressupostos_Assumpt!C61*MAX(0,Pressupostos_Assumpt!C56-Pressupostos_Assumpt!C57)*Pressupostos_Assumpt!C58*Pressupostos_Assumpt!C42*Operacao_Operations!J5 -> 125.52715 | K27: =(K23+K24)*Pressupostos_Assumpt!C42+Pressupostos_Assumpt!C61*MAX(0,Pressupostos_Assumpt!C56-Pressupostos_Assumpt!C57)*Pressupostos_Assumpt!C58*Pressupostos_Assumpt!C42*Operacao_Operations!K5 -> 552.31944 | L27: =(L23+L24)*Pressupostos_Assumpt!C42+Pressupostos_Assumpt!C61*MAX(0,Pressupostos_Assumpt!C56-Pressupostos_Assumpt!C57)*Pressupostos_Assumpt!C58*Pressupostos_Assumpt!C42*Operacao_Operations!L5 -> 552.31944 | M27: =(M23+M24)*Pressupostos_Assumpt!D42+Pressupostos_Assumpt!D61*MAX(0,Pressupostos_Assumpt!D56-Pressupostos_Assumpt!D57)*Pressupostos_Assumpt!D58*Pressupostos_Assumpt!D42*Operacao_Operations!M5 -> 1707.3875 | N27: =(N23+N24)*Pressupostos_Assumpt!D42+Pressupostos_Assumpt!D61*MAX(0,Pressupostos_Assumpt!D56-Pressupostos_Assumpt!D57)*Pressupostos_Assumpt!D58*Pressupostos_Assumpt!D42*Operacao_Operations!N5 -> 1707.3875 | O27: =(O23+O24)*Pressupostos_Assumpt!D42+Pressupostos_Assumpt!D61*MAX(0,Pressupostos_Assumpt!D56-Pressupostos_Assumpt!D57)*Pressupostos_Assumpt!D58*Pressupostos_Assumpt!D42*Operacao_Operations!O5 -> 1707.3875 | P27: =(P23+P24)*Pressupostos_Assumpt!D42+Pressupostos_Assumpt!D61*MAX(0,Pressupostos_Assumpt!D56-Pressupostos_Assumpt!D57)*Pressupostos_Assumpt!D58*Pressupostos_Assumpt!D42*Operacao_Operations!P5 -> 569.12917 | Q27: =(Q23+Q24)*Pressupostos_Assumpt!D42+Pressupostos_Assumpt!D61*MAX(0,Pressupostos_Assumpt!D56-Pressupostos_Assumpt!D57)*Pressupostos_Assumpt!D58*Pressupostos_Assumpt!D42*Operacao_Operations!Q5 -> 569.12917 | R27: =(R23+R24)*Pressupostos_Assumpt!D42+Pressupostos_Assumpt!D61*MAX(0,Pressupostos_Assumpt!D56-Pressupostos_Assumpt!D57)*Pressupostos_Assumpt!D58*Pressupostos_Assumpt!D42*Operacao_Operations!R5 -> 569.12917 | S27: =C27+D27+E27+F27+G27+H27+I27+J27+K27+L27 -> 2108.8561 | T27: =M27+N27+O27+P27+Q27+R27 -> 6829.55
B28: CUSTO EMPRESA Gestor / TOTAL MANAGER COST | C28: =C26+C27 -> 684.0625 | D28: =D26+D27 -> 684.0625 | E28: =E26+E27 -> 684.0625 | F28: =F26+F27 -> 684.0625 | G28: =G26+G27 -> 684.0625 | H28: =H26+H27 -> 684.0625 | I28: =I26+I27 -> 684.0625 | J28: =J26+J27 -> 684.0625 | ... R28: =R26+R27 -> 3097.4625 | S28: =C28+D28+E28+F28+G28+H28+I28+J28+K28+L28 -> 11492.25 | T28: =M28+N28+O28+P28+Q28+R28 -> 37169.55
B30: D. ASSISTENTE ADMINISTRATIVO / ADMIN ASSISTANT
