Workbook

Sheet Capa_Cover
B2: PLANO DE NEGOCIOS / BUSINESS PLAN
B3: Aluguer de Campervans / Campervan Rental — Portugal
B4: Pequeno negocio / Small business • Ano 1 mensal + resumo 3 anos / Year 1 monthly + 3-yr summary
B6: PARAMETROS-CHAVE / KEY PARAMETERS
B7: Carrinha / Campervan | C7: =Pressupostos_Assumpt!C7 -> 40000 | D7: EUR (equipada)
B8: Financiamento / Financing | C8: =Pressupostos_Assumpt!C9 -> 36000 | D8: EUR a credito
B9: Prazo credito / Loan term | C9: =Pressupostos_Assumpt!C11 -> 7 | D9: anos @ TAEG
B10: Frota / Fleet | C10: 1 carrinha / 1 van | D10: modelo de 1 carrinha
B11: km compra -> venda / km buy->sell | C11: 80k -> 200k | D11: vende ao atingir alvo
B12: Preco epoca alta / High-season price | C12: =Pressupostos_Assumpt!C20 -> 160 | D12: EUR/dia
B13: Ocupacao media / Avg occupancy | C13: =Receita_Revenue!O11/Receita_Revenue!O8 -> 0.48451613 | D13: dias alug./disponiveis
B15: ESTRUTURA / STRUCTURE
B16: 1. Pressupostos / Assumptions | C16: Inputs a azul / blue inputs
B17: 2. Financiamento / Loan | C17: Tabela price 84 meses
B18: 3. Receita / Revenue | C18: Ocupacao x preco por epoca
B19: 4. Custos / Costs | C19: Variaveis + fixos + negocio
B20: 5. DRE / P&L | C20: Resultados mensais Ano 1
B21: 6. Resumo Multianual / Multi-year | C21: Ano 1->venda, c/ a venda incluida
B22: 7. Tesouraria / Cash Flow | C22: Caixa mensal Ano 1 c/ IVA
B23: 8. Ponto Critico / Break-Even | C23: Dias e ocupacao criticos
B24: 9. Sensibilidades / Sensitivity | C24: Lucro vs ocupacao e preco
B25: 10. Quilometragem / Mileage | C25: km ao longo do tempo (80k->200k)
B26: 11. Venda / Resale | C26: Valor de revenda e quando vender
B28: Nota: valores de mercado PT (Yescapa/Goboony, CoolDrive, CamperDays). Edite as celulas a AZUL no separador Pressupostos.
B29: Note: PT market figures. Edit the BLUE cells in the Assumptions tab to run your own scenarios.

Sheet Pressupostos_Assumpt
B2: PRESSUPOSTOS / ASSUMPTIONS
B3: Aluguer de campervans / Campervan rental — edite as celulas a AZUL / edit the BLUE cells
B5: A. VEICULO E FINANCIAMENTO / VEHICLE & FINANCING
B6: Parametro / Parameter | C6: Valor / Value | D6: Unid./Unit | E6: Fonte-Nota / Source-Note
B7: Preco compra carrinha / Purchase price (c/ conversao) | C7: 40000 | D7: EUR | E7: Campervan equipada ~40k (mercado PT)
B8: Entrada / Down payment | C8: 0.1 | D8: % | E8: 10% de entrada, resto a credito
B9: Valor financiado / Amount financed | C9: =Pressupostos_Assumpt!C7*(1-Pressupostos_Assumpt!C8) -> 36000 | D9: EUR | E9: Calculado
B10: Entrada (valor) / Down payment value | C10: =Pressupostos_Assumpt!C7*Pressupostos_Assumpt!C8 -> 4000 | D10: EUR | E10: Calculado
B11: Prazo credito / Loan term | C11: 7 | D11: anos | E11: Credito automovel/pessoal
B12: Taxa juro anual (TAEG) / Annual rate | C12: 0.08 | D12: % | E12: TAEG estimada credito PT 2026
B13: Vida util / Useful life | C13: 8 | D13: anos | E13: Depreciacao linear
B14: Valor residual / Residual value | C14: 8000 | D14: EUR | E14: Valor de revenda estimado
B15: Depreciacao anual / Annual depreciation | C15: =(Pressupostos_Assumpt!C7-Pressupostos_Assumpt!C14)/Pressupostos_Assumpt!C13 -> 4000 | D15: EUR/ano | E15: Linear: (compra-residual)/vida
B16: B. PRECOS POR EPOCA / PRICING BY SEASON (por dia / per day)
B17: Parametro / Parameter | C17: Valor / Value | D17: Unid./Unit | E17: Fonte-Nota / Source-Note
B18: Epoca baixa / Low (Nov-Mar) | C18: 65 | D18: EUR/dia | E18: Mercado PT: 50-70 EUR/dia
B19: Epoca media / Shoulder (Abr-Mai, Out) | C19: 105 | D19: EUR/dia | E19: Mercado PT: 90-120 EUR/dia
B20: Epoca alta / High (Jun-Set) | C20: 160 | D20: EUR/dia | E20: Mercado PT: 150-175 EUR/dia
B21: Crescimento preco anual / Annual price growth | C21: 0.03 | D21: % | E21: Inflacao/posicionamento
B22: C. OCUPACAO POR EPOCA / OCCUPANCY BY SEASON (% dias disponiveis)
B23: Parametro / Parameter | C23: Valor / Value | D23: Unid./Unit | E23: Fonte-Nota / Source-Note
B24: Epoca baixa / Low | C24: 0.22 | D24: % | E24: Operador pequeno: ~25% off-peak
B25: Epoca media / Shoulder | C25: 0.5 | D25: % | E25: Media anual setor ~55%
B26: Epoca alta / High | C26: 0.8 | D26: % | E26: Pico verao 80-90%
B27: D. EXTRAS, COMISSOES E OPERACAO / EXTRAS, FEES & OPERATIONS
B28: Parametro / Parameter | C28: Valor / Value | D28: Unid./Unit | E28: Fonte-Nota / Source-Note
B29: Receita extras (% s/ aluguer) / Extras revenue | C29: 0.12 | D29: % | E29: Limpeza, kit, km, seguro extra
B30: Comissao plataforma / Platform commission | C30: 0.15 | D30: % | E30: Yescapa/Goboony (status profissional)
B31: Duracao media reserva / Avg booking length | C31: 6 | D31: dias | E31: Media setor ~6-7 dias
B32: Custo limpeza+consumiveis / Cleaning+consumables | C32: 40 | D32: EUR/reserva | E32: Limpeza, lavandaria, gas, quimicos
B33: Dias indisponiveis/mes / Unavailable days per month | C33: 2 | D33: dias | E33: Manutencao/limpeza entre reservas
B34: E. CUSTOS FIXOS POR CARRINHA / FIXED COSTS PER VAN
B35: Parametro / Parameter | C35: Valor / Value | D35: Unid./Unit | E35: Fonte-Nota / Source-Note
B36: Seguro comercial / Commercial insurance | C36: 150 | D36: EUR/mes | E36: Seguro aluguer (s/ IVA)
B37: Manutencao+pneus / Maintenance+tyres | C37: 70 | D37: EUR/mes | E37: Revisoes, pneus, desgaste
B38: Parqueamento / Parking | C38: 50 | D38: EUR/mes | E38: Lugar quando parada
B39: IUC (imposto circulacao) / Road tax | C39: 250 | D39: EUR/ano | E39: Imposto unico circulacao
B40: Inspecao IPO / Inspection | C40: 40 | D40: EUR/ano | E40: Inspecao periodica
B41: Assistencia em viagem / Breakdown assist. | C41: 120 | D41: EUR/ano | E41: Assistencia 24/7
B42: F. CUSTOS FIXOS DO NEGOCIO / BUSINESS OVERHEAD (nao por carrinha)
...

Sheet Financiamento_Loan
B2: FINANCIAMENTO / LOAN AMORTIZATION (1 carrinha / per van)
B3: Tabela price (prestacao constante) / French amortization
B5: Capital financiado / Principal | C5: =Pressupostos_Assumpt!C9 -> 36000
B6: Taxa mensal / Monthly rate | C6: =Pressupostos_Assumpt!C12/12 -> 0.0066666667
B7: N. prestacoes / Payments | C7: =Pressupostos_Assumpt!C11*12 -> 84
B8: Prestacao mensal / Monthly payment (PMT) | C8: =PMT(C6,C7,-C5) -> 561.10372
B10: Mes/Month | C10: Saldo inicial/Open | D10: Juro/Interest | E10: Capital/Principal | F10: Saldo final/Close
B11: 1 | C11: =C5 -> 36000 | D11: =C11*$C$6 -> 240 | E11: =$C$8-D11 -> 321.10372 | F11: =C11-E11 -> 35678.896
B12: 2 | C12: =F11 -> 35678.896 | D12: =C12*$C$6 -> 237.85931 | E12: =$C$8-D12 -> 323.24441 | F12: =C12-E12 -> 35355.652
B13: 3 | C13: =F12 -> 35355.652 | D13: =C13*$C$6 -> 235.70435 | E13: =$C$8-D13 -> 325.39937 | F13: =C13-E13 -> 35030.252
B14: 4 | C14: =F13 -> 35030.252 | D14: =C14*$C$6 -> 233.53502 | E14: =$C$8-D14 -> 327.5687 | F14: =C14-E14 -> 34702.684
B15: 5 | C15: =F14 -> 34702.684 | D15: =C15*$C$6 -> 231.35123 | E15: =$C$8-D15 -> 329.75249 | F15: =C15-E15 -> 34372.931
B16: 6 | C16: =F15 -> 34372.931 | D16: =C16*$C$6 -> 229.15288 | E16: =$C$8-D16 -> 331.95084 | F16: =C16-E16 -> 34040.98
B17: 7 | C17: =F16 -> 34040.98 | D17: =C17*$C$6 -> 226.93987 | E17: =$C$8-D17 -> 334.16385 | F17: =C17-E17 -> 33706.817
B18: 8 | C18: =F17 -> 33706.817 | D18: =C18*$C$6 -> 224.71211 | E18: =$C$8-D18 -> 336.39161 | F18: =C18-E18 -> 33370.425
B19: 9 | C19: =F18 -> 33370.425 | D19: =C19*$C$6 -> 222.4695 | E19: =$C$8-D19 -> 338.63422 | F19: =C19-E19 -> 33031.791
B20: 10 | C20: =F19 -> 33031.791 | D20: =C20*$C$6 -> 220.21194 | E20: =$C$8-D20 -> 340.89178 | F20: =C20-E20 -> 32690.899
B21: 11 | C21: =F20 -> 32690.899 | D21: =C21*$C$6 -> 217.93933 | E21: =$C$8-D21 -> 343.16439 | F21: =C21-E21 -> 32347.735
B22: 12 | C22: =F21 -> 32347.735 | D22: =C22*$C$6 -> 215.65156 | E22: =$C$8-D22 -> 345.45215 | F22: =C22-E22 -> 32002.282
B23: 13 | C23: =F22 -> 32002.282 | D23: =C23*$C$6 -> 213.34855 | E23: =$C$8-D23 -> 347.75517 | F23: =C23-E23 -> 31654.527
... B94: 84 | C94: =F93 -> 557.3878 | D94: =C94*$C$6 -> 3.7159187 | E94: =$C$8-D94 -> 557.3878 | F94: =C94-E94 -> -1.546141e-11
B96: RESUMO ANUAL DO EMPRESTIMO / ANNUAL LOAN SUMMARY (1 carrinha)
B97: Ano do emprestimo / Loan year | C97: Juro / Interest | D97: Capital / Principal
B98: 1 | C98: =SUM(D11:D22) -> 2735.5271 | D98: =SUM(E11:E22) -> 3997.7175
B99: 2 | C99: =SUM(D23:D34) -> 2403.7185 | D99: =SUM(E23:E34) -> 4329.5261
B100: 3 | C100: =SUM(D35:D46) -> 2044.37 | D100: =SUM(E35:E46) -> 4688.8747
B101: 4 | C101: =SUM(D47:D58) -> 1655.1957 | D101: =SUM(E47:E58) -> 5078.0489
B102: 5 | C102: =SUM(D59:D70) -> 1233.7201 | D102: =SUM(E59:E70) -> 5499.5245
B103: 6 | C103: =SUM(D71:D82) -> 777.2623 | D103: =SUM(E71:E82) -> 5955.9823
B104: 7 | C104: =SUM(D83:D94) -> 282.91871 | D104: =SUM(E83:E94) -> 6450.3259

Sheet Receita_Revenue
B2: RECEITA / REVENUE - Ano 1 mensal / Year 1 monthly (1 carrinha)
B3: Ocupacao x preco, ajustado a epoca / Occupancy x price, season-adjusted
B5: Rubrica / Item | C5: Jan | D5: Fev | E5: Mar | F5: Abr | G5: Mai | H5: Jun | I5: Jul | J5: Ago | K5: Set | L5: Out | M5: Nov | N5: Dez | O5: Total Ano 1
B6: Epoca / Season | C6: B | D6: B | E6: B | F6: M | G6: M | H6: A | I6: A | J6: A | K6: A | L6: M | M6: B | N6: B
B7: Dias do mes / Days in month | C7: 31 | D7: 28 | E7: 31 | F7: 30 | G7: 31 | H7: 30 | I7: 31 | J7: 31 | K7: 30 | L7: 31 | M7: 30 | N7: 31 | O7: =SUM(C7:N7) -> 365
B8: Dias disponiveis / Available days | C8: =C7-Pressupostos_Assumpt!C33 -> 29 | D8: =D7-Pressupostos_Assumpt!C33 -> 26 | E8: =E7-Pressupostos_Assumpt!C33 -> 29 | F8: =F7-Pressupostos_Assumpt!C33 -> 28 | G8: =G7-Pressupostos_Assumpt!C33 -> 29 | H8: =H7-Pressupostos_Assumpt!C33 -> 28 | I8: =I7-Pressupostos_Assumpt!C33 -> 29 | J8: =J7-Pressupostos_Assumpt!C33 -> 29 | K8: =K7-Pressupostos_Assumpt!C33 -> 28 | L8: =L7-Pressupostos_Assumpt!C33 -> 29 | M8: =M7-Pressupostos_Assumpt!C33 -> 28 | N8: =N7-Pressupostos_Assumpt!C33 -> 29 | O8: =SUM(C8:N8) -> 341
B9: Ocupacao / Occupancy | C9: =IF(C6="A",Pressupostos_Assumpt!C26,IF(C6="M",Pressupostos_Assumpt!C25,Pressupostos_Assumpt!C24)) -> 0.22 | D9: =IF(D6="A",Pressupostos_Assumpt!C26,IF(D6="M",Pressupostos_Assumpt!C25,Pressupostos_Assumpt!C24)) -> 0.22 | E9: =IF(E6="A",Pressupostos_Assumpt!C26,IF(E6="M",Pressupostos_Assumpt!C25,Pressupostos_Assumpt!C24)) -> 0.22 | F9: =IF(F6="A",Pressupostos_Assumpt!C26,IF(F6="M",Pressupostos_Assumpt!C25,Pressupostos_Assumpt!C24)) -> 0.5 | G9: =IF(G6="A",Pressupostos_Assumpt!C26,IF(G6="M",Pressupostos_Assumpt!C25,Pressupostos_Assumpt!C24)) -> 0.5 | H9: =IF(H6="A",Pressupostos_Assumpt!C26,IF(H6="M",Pressupostos_Assumpt!C25,Pressupostos_Assumpt!C24)) -> 0.8 | I9: =IF(I6="A",Pressupostos_Assumpt!C26,IF(I6="M",Pressupostos_Assumpt!C25,Pressupostos_Assumpt!C24)) -> 0.8 | J9: =IF(J6="A",Pressupostos_Assumpt!C26,IF(J6="M",Pressupostos_Assumpt!C25,Pressupostos_Assumpt!C24)) -> 0.8 | K9: =IF(K6="A",Pressupostos_Assumpt!C26,IF(K6="M",Pressupostos_Assumpt!C25,Pressupostos_Assumpt!C24)) -> 0.8 | L9: =IF(L6="A",Pressupostos_Assumpt!C26,IF(L6="M",Pressupostos_Assumpt!C25,Pressupostos_Assumpt!C24)) -> 0.5 | M9: =IF(M6="A",Pressupostos_Assumpt!C26,IF(M6="M",Pressupostos_Assumpt!C25,Pressupostos_Assumpt!C24)) -> 0.22 | N9: =IF(N6="A",Pressupostos_Assumpt!C26,IF(N6="M",Pressupostos_Assumpt!C25,Pressupostos_Assumpt!C24)) -> 0.22 | O9: =AVERAGE(C9:N9) -> 0.48333333
B10: Preco/dia / Daily rate | C10: =IF(C6="A",Pressupostos_Assumpt!C20,IF(C6="M",Pressupostos_Assumpt!C19,Pressupostos_Assumpt!C18)) -> 65 | D10: =IF(D6="A",Pressupostos_Assumpt!C20,IF(D6="M",Pressupostos_Assumpt!C19,Pressupostos_Assumpt!C18)) -> 65 | E10: =IF(E6="A",Pressupostos_Assumpt!C20,IF(E6="M",Pressupostos_Assumpt!C19,Pressupostos_Assumpt!C18)) -> 65 | F10: =IF(F6="A",Pressupostos_Assumpt!C20,IF(F6="M",Pressupostos_Assumpt!C19,Pressupostos_Assumpt!C18)) -> 105 | G10: =IF(G6="A",Pressupostos_Assumpt!C20,IF(G6="M",Pressupostos_Assumpt!C19,Pressupostos_Assumpt!C18)) -> 105 | H10: =IF(H6="A",Pressupostos_Assumpt!C20,IF(H6="M",Pressupostos_Assumpt!C19,Pressupostos_Assumpt!C18)) -> 160 | I10: =IF(I6="A",Pressupostos_Assumpt!C20,IF(I6="M",Pressupostos_Assumpt!C19,Pressupostos_Assumpt!C18)) -> 160 | J10: =IF(J6="A",Pressupostos_Assumpt!C20,IF(J6="M",Pressupostos_Assumpt!C19,Pressupostos_Assumpt!C18)) -> 160 | K10: =IF(K6="A",Pressupostos_Assumpt!C20,IF(K6="M",Pressupostos_Assumpt!C19,Pressupostos_Assumpt!C18)) -> 160 | L10: =IF(L6="A",Pressupostos_Assumpt!C20,IF(L6="M",Pressupostos_Assumpt!C19,Pressupostos_Assumpt!C18)) -> 105 | M10: =IF(M6="A",Pressupostos_Assumpt!C20,IF(M6="M",Pressupostos_Assumpt!C19,Pressupostos_Assumpt!C18)) -> 65 | N10: =IF(N6="A",Pressupostos_Assumpt!C20,IF(N6="M",Pressupostos_Assumpt!C19,Pressupostos_Assumpt!C18)) -> 65 | O10: =AVERAGE(C10:N10) -> 106.66667
B11: Dias alugados / Rented days | C11: =C8*C9 -> 6.38 | D11: =D8*D9 -> 5.72 | E11: =E8*E9 -> 6.38 | F11: =F8*F9 -> 14 | G11: =G8*G9 -> 14.5 | H11: =H8*H9 -> 22.4 | I11: =I8*I9 -> 23.2 | J11: =J8*J9 -> 23.2 | ... N11: =N8*N9 -> 6.38 | O11: =SUM(C11:N11) -> 165.22
B12: Receita aluguer / Rental revenue | C12: =C11*C10 -> 414.7 | D12: =D11*D10 -> 371.8 | E12: =E11*E10 -> 414.7 | F12: =F11*F10 -> 1470 | G12: =G11*G10 -> 1522.5 | H12: =H11*H10 -> 3584 | I12: =I11*I10 -> 3712 | J12: =J11*J10 -> 3712 | ... N12: =N11*N10 -> 414.7 | O12: =SUM(C12:N12) -> 21123.3
B13: Receita extras / Extras revenue | C13: =C12*Pressupostos_Assumpt!C29 -> 49.764 | D13: =D12*Pressupostos_Assumpt!C29 -> 44.616 | E13: =E12*Pressupostos_Assumpt!C29 -> 49.764 | F13: =F12*Pressupostos_Assumpt!C29 -> 176.4 | G13: =G12*Pressupostos_Assumpt!C29 -> 182.7 | H13: =H12*Pressupostos_Assumpt!C29 -> 430.08 | I13: =I12*Pressupostos_Assumpt!C29 -> 445.44 | J13: =J12*Pressupostos_Assumpt!C29 -> 445.44 | K13: =K12*Pressupostos_Assumpt!C29 -> 430.08 | L13: =L12*Pressupostos_Assumpt!C29 -> 182.7 | M13: =M12*Pressupostos_Assumpt!C29 -> 48.048 | N13: =N12*Pressupostos_Assumpt!C29 -> 49.764 | O13: =SUM(C13:N13) -> 2534.796
B14: RECEITA TOTAL / TOTAL REVENUE | C14: =C12+C13 -> 464.464 | D14: =D12+D13 -> 416.416 | E14: =E12+E13 -> 464.464 | F14: =F12+F13 -> 1646.4 | G14: =G12+G13 -> 1705.2 | H14: =H12+H13 -> 4014.08 | I14: =I12+I13 -> 4157.44 | J14: =J12+J13 -> 4157.44 | ... N14: =N12+N13 -> 464.464 | O14: =SUM(C14:N14) -> 23658.096
B15: N. reservas / Bookings | C15: =C11/Pressupostos_Assumpt!C31 -> 1.0633333 | D15: =D11/Pressupostos_Assumpt!C31 -> 0.95333333 | E15: =E11/Pressupostos_Assumpt!C31 -> 1.0633333 | F15: =F11/Pressupostos_Assumpt!C31 -> 2.3333333 | G15: =G11/Pressupostos_Assumpt!C31 -> 2.4166667 | H15: =H11/Pressupostos_Assumpt!C31 -> 3.7333333 | I15: =I11/Pressupostos_Assumpt!C31 -> 3.8666667 | J15: =J11/Pressupostos_Assumpt!C31 -> 3.8666667 | K15: =K11/Pressupostos_Assumpt!C31 -> 3.7333333 | L15: =L11/Pressupostos_Assumpt!C31 -> 2.4166667 | M15: =M11/Pressupostos_Assumpt!C31 -> 1.0266667 | N15: =N11/Pressupostos_Assumpt!C31 -> 1.0633333 | O15: =SUM(C15:N15) -> 27.536667

Sheet Custos_Costs
B2: CUSTOS / COSTS - Ano 1 mensal / Year 1 monthly (1 carrinha)
B3: Variaveis (por reserva) + fixos (por carrinha) + negocio / Variable + fixed + overhead
B5: Rubrica / Item | C5: Jan | D5: Fev | E5: Mar | F5: Abr | G5: Mai | H5: Jun | I5: Jul | J5: Ago | K5: Set | L5: Out | M5: Nov | N5: Dez | O5: Total Ano 1
B6: VARIAVEIS / VARIABLE
B7: Comissao plataforma / Platform commission | C7: =Receita_Revenue!C14*Pressupostos_Assumpt!C30 -> 69.6696 | D7: =Receita_Revenue!D14*Pressupostos_Assumpt!C30 -> 62.4624 | E7: =Receita_Revenue!E14*Pressupostos_Assumpt!C30 -> 69.6696 | F7: =Receita_Revenue!F14*Pressupostos_Assumpt!C30 -> 246.96 | G7: =Receita_Revenue!G14*Pressupostos_Assumpt!C30 -> 255.78 | H7: =Receita_Revenue!H14*Pressupostos_Assumpt!C30 -> 602.112 | I7: =Receita_Revenue!I14*Pressupostos_Assumpt!C30 -> 623.616 | J7: =Receita_Revenue!J14*Pressupostos_Assumpt!C30 -> 623.616 | K7: =Receita_Revenue!K14*Pressupostos_Assumpt!C30 -> 602.112 | L7: =Receita_Revenue!L14*Pressupostos_Assumpt!C30 -> 255.78 | M7: =Receita_Revenue!M14*Pressupostos_Assumpt!C30 -> 67.2672 | N7: =Receita_Revenue!N14*Pressupostos_Assumpt!C30 -> 69.6696 | O7: =SUM(C7:N7) -> 3548.7144
B8: Limpeza+consumiveis / Cleaning+consumables | C8: =Receita_Revenue!C15*Pressupostos_Assumpt!C32 -> 42.533333 | D8: =Receita_Revenue!D15*Pressupostos_Assumpt!C32 -> 38.133333 | E8: =Receita_Revenue!E15*Pressupostos_Assumpt!C32 -> 42.533333 | F8: =Receita_Revenue!F15*Pressupostos_Assumpt!C32 -> 93.333333 | G8: =Receita_Revenue!G15*Pressupostos_Assumpt!C32 -> 96.666667 | H8: =Receita_Revenue!H15*Pressupostos_Assumpt!C32 -> 149.33333 | I8: =Receita_Revenue!I15*Pressupostos_Assumpt!C32 -> 154.66667 | J8: =Receita_Revenue!J15*Pressupostos_Assumpt!C32 -> 154.66667 | K8: =Receita_Revenue!K15*Pressupostos_Assumpt!C32 -> 149.33333 | L8: =Receita_Revenue!L15*Pressupostos_Assumpt!C32 -> 96.666667 | M8: =Receita_Revenue!M15*Pressupostos_Assumpt!C32 -> 41.066667 | N8: =Receita_Revenue!N15*Pressupostos_Assumpt!C32 -> 42.533333 | O8: =SUM(C8:N8) -> 1101.4667
B9: Subtotal variaveis / Subtotal variable | C9: =C7+C8 -> 112.20293 | D9: =D7+D8 -> 100.59573 | E9: =E7+E8 -> 112.20293 | F9: =F7+F8 -> 340.29333 | G9: =G7+G8 -> 352.44667 | H9: =H7+H8 -> 751.44533 | I9: =I7+I8 -> 778.28267 | J9: =J7+J8 -> 778.28267 | ... N9: =N7+N8 -> 112.20293 | O9: =SUM(C9:N9) -> 4650.1811
B10: FIXOS POR CARRINHA / FIXED PER VAN (x carrinhas Ano 1)
B11: Seguro / Insurance | C11: =Pressupostos_Assumpt!C36*Pressupostos_Assumpt!C50 -> 150 | D11: =Pressupostos_Assumpt!C36*Pressupostos_Assumpt!C50 -> 150 | E11: =Pressupostos_Assumpt!C36*Pressupostos_Assumpt!C50 -> 150 | F11: =Pressupostos_Assumpt!C36*Pressupostos_Assumpt!C50 -> 150 | G11: =Pressupostos_Assumpt!C36*Pressupostos_Assumpt!C50 -> 150 | H11: =Pressupostos_Assumpt!C36*Pressupostos_Assumpt!C50 -> 150 | I11: =Pressupostos_Assumpt!C36*Pressupostos_Assumpt!C50 -> 150 | J11: =Pressupostos_Assumpt!C36*Pressupostos_Assumpt!C50 -> 150 | K11: =Pressupostos_Assumpt!C36*Pressupostos_Assumpt!C50 -> 150 | L11: =Pressupostos_Assumpt!C36*Pressupostos_Assumpt!C50 -> 150 | M11: =Pressupostos_Assumpt!C36*Pressupostos_Assumpt!C50 -> 150 | N11: =Pressupostos_Assumpt!C36*Pressupostos_Assumpt!C50 -> 150 | O11: =SUM(C11:N11) -> 1800
B12: Manutencao+pneus / Maintenance | C12: =Pressupostos_Assumpt!C37*Pressupostos_Assumpt!C50 -> 70 | D12: =Pressupostos_Assumpt!C37*Pressupostos_Assumpt!C50 -> 70 | E12: =Pressupostos_Assumpt!C37*Pressupostos_Assumpt!C50 -> 70 | F12: =Pressupostos_Assumpt!C37*Pressupostos_Assumpt!C50 -> 70 | G12: =Pressupostos_Assumpt!C37*Pressupostos_Assumpt!C50 -> 70 | H12: =Pressupostos_Assumpt!C37*Pressupostos_Assumpt!C50 -> 70 | I12: =Pressupostos_Assumpt!C37*Pressupostos_Assumpt!C50 -> 70 | J12: =Pressupostos_Assumpt!C37*Pressupostos_Assumpt!C50 -> 70 | K12: =Pressupostos_Assumpt!C37*Pressupostos_Assumpt!C50 -> 70 | L12: =Pressupostos_Assumpt!C37*Pressupostos_Assumpt!C50 -> 70 | M12: =Pressupostos_Assumpt!C37*Pressupostos_Assumpt!C50 -> 70 | N12: =Pressupostos_Assumpt!C37*Pressupostos_Assumpt!C50 -> 70 | O12: =SUM(C12:N12) -> 840
B13: Parqueamento / Parking | C13: =Pressupostos_Assumpt!C38*Pressupostos_Assumpt!C50 -> 50 | D13: =Pressupostos_Assumpt!C38*Pressupostos_Assumpt!C50 -> 50 | E13: =Pressupostos_Assumpt!C38*Pressupostos_Assumpt!C50 -> 50 | F13: =Pressupostos_Assumpt!C38*Pressupostos_Assumpt!C50 -> 50 | G13: =Pressupostos_Assumpt!C38*Pressupostos_Assumpt!C50 -> 50 | H13: =Pressupostos_Assumpt!C38*Pressupostos_Assumpt!C50 -> 50 | I13: =Pressupostos_Assumpt!C38*Pressupostos_Assumpt!C50 -> 50 | J13: =Pressupostos_Assumpt!C38*Pressupostos_Assumpt!C50 -> 50 | K13: =Pressupostos_Assumpt!C38*Pressupostos_Assumpt!C50 -> 50 | L13: =Pressupostos_Assumpt!C38*Pressupostos_Assumpt!C50 -> 50 | M13: =Pressupostos_Assumpt!C38*Pressupostos_Assumpt!C50 -> 50 | N13: =Pressupostos_Assumpt!C38*Pressupostos_Assumpt!C50 -> 50 | O13: =SUM(C13:N13) -> 600
B14: IUC / Road tax (1/12) | C14: =Pressupostos_Assumpt!C39/12*Pressupostos_Assumpt!C50 -> 20.833333 | D14: =Pressupostos_Assumpt!C39/12*Pressupostos_Assumpt!C50 -> 20.833333 | E14: =Pressupostos_Assumpt!C39/12*Pressupostos_Assumpt!C50 -> 20.833333 | F14: =Pressupostos_Assumpt!C39/12*Pressupostos_Assumpt!C50 -> 20.833333 | G14: =Pressupostos_Assumpt!C39/12*Pressupostos_Assumpt!C50 -> 20.833333 | H14: =Pressupostos_Assumpt!C39/12*Pressupostos_Assumpt!C50 -> 20.833333 | I14: =Pressupostos_Assumpt!C39/12*Pressupostos_Assumpt!C50 -> 20.833333 | J14: =Pressupostos_Assumpt!C39/12*Pressupostos_Assumpt!C50 -> 20.833333 | K14: =Pressupostos_Assumpt!C39/12*Pressupostos_Assumpt!C50 -> 20.833333 | L14: =Pressupostos_Assumpt!C39/12*Pressupostos_Assumpt!C50 -> 20.833333 | M14: =Pressupostos_Assumpt!C39/12*Pressupostos_Assumpt!C50 -> 20.833333 | N14: =Pressupostos_Assumpt!C39/12*Pressupostos_Assumpt!C50 -> 20.833333 | O14: =SUM(C14:N14) -> 250
B15: IPO / Inspection (1/12) | C15: =Pressupostos_Assumpt!C40/12*Pressupostos_Assumpt!C50 -> 3.3333333 | D15: =Pressupostos_Assumpt!C40/12*Pressupostos_Assumpt!C50 -> 3.3333333 | E15: =Pressupostos_Assumpt!C40/12*Pressupostos_Assumpt!C50 -> 3.3333333 | F15: =Pressupostos_Assumpt!C40/12*Pressupostos_Assumpt!C50 -> 3.3333333 | G15: =Pressupostos_Assumpt!C40/12*Pressupostos_Assumpt!C50 -> 3.3333333 | H15: =Pressupostos_Assumpt!C40/12*Pressupostos_Assumpt!C50 -> 3.3333333 | I15: =Pressupostos_Assumpt!C40/12*Pressupostos_Assumpt!C50 -> 3.3333333 | J15: =Pressupostos_Assumpt!C40/12*Pressupostos_Assumpt!C50 -> 3.3333333 | K15: =Pressupostos_Assumpt!C40/12*Pressupostos_Assumpt!C50 -> 3.3333333 | L15: =Pressupostos_Assumpt!C40/12*Pressupostos_Assumpt!C50 -> 3.3333333 | M15: =Pressupostos_Assumpt!C40/12*Pressupostos_Assumpt!C50 -> 3.3333333 | N15: =Pressupostos_Assumpt!C40/12*Pressupostos_Assumpt!C50 -> 3.3333333 | O15: =SUM(C15:N15) -> 40
B16: Assistencia / Breakdown (1/12) | C16: =Pressupostos_Assumpt!C41/12*Pressupostos_Assumpt!C50 -> 10 | D16: =Pressupostos_Assumpt!C41/12*Pressupostos_Assumpt!C50 -> 10 | E16: =Pressupostos_Assumpt!C41/12*Pressupostos_Assumpt!C50 -> 10 | F16: =Pressupostos_Assumpt!C41/12*Pressupostos_Assumpt!C50 -> 10 | G16: =Pressupostos_Assumpt!C41/12*Pressupostos_Assumpt!C50 -> 10 | H16: =Pressupostos_Assumpt!C41/12*Pressupostos_Assumpt!C50 -> 10 | I16: =Pressupostos_Assumpt!C41/12*Pressupostos_Assumpt!C50 -> 10 | J16: =Pressupostos_Assumpt!C41/12*Pressupostos_Assumpt!C50 -> 10 | K16: =Pressupostos_Assumpt!C41/12*Pressupostos_Assumpt!C50 -> 10 | L16: =Pressupostos_Assumpt!C41/12*Pressupostos_Assumpt!C50 -> 10 | M16: =Pressupostos_Assumpt!C41/12*Pressupostos_Assumpt!C50 -> 10 | N16: =Pressupostos_Assumpt!C41/12*Pressupostos_Assumpt!C50 -> 10 | O16: =SUM(C16:N16) -> 120
B17: Subtotal fixos carrinha / Subtotal per-van | C17: =C11+C12+C13+C14+C15+C16 -> 304.16667 | D17: =D11+D12+D13+D14+D15+D16 -> 304.16667 | E17: =E11+E12+E13+E14+E15+E16 -> 304.16667 | F17: =F11+F12+F13+F14+F15+F16 -> 304.16667 | G17: =G11+G12+G13+G14+G15+G16 -> 304.16667 | H17: =H11+H12+H13+H14+H15+H16 -> 304.16667 | I17: =I11+I12+I13+I14+I15+I16 -> 304.16667 | J17: =J11+J12+J13+J14+J15+J16 -> 304.16667 | ... N17: =N11+N12+N13+N14+N15+N16 -> 304.16667 | O17: =SUM(C17:N17) -> 3650
B18: NEGOCIO / OVERHEAD
B19: Contabilidade / Accounting | C19: =Pressupostos_Assumpt!C44 -> 100 | D19: =Pressupostos_Assumpt!C44 -> 100 | E19: =Pressupostos_Assumpt!C44 -> 100 | F19: =Pressupostos_Assumpt!C44 -> 100 | G19: =Pressupostos_Assumpt!C44 -> 100 | H19: =Pressupostos_Assumpt!C44 -> 100 | I19: =Pressupostos_Assumpt!C44 -> 100 | J19: =Pressupostos_Assumpt!C44 -> 100 | K19: =Pressupostos_Assumpt!C44 -> 100 | L19: =Pressupostos_Assumpt!C44 -> 100 | M19: =Pressupostos_Assumpt!C44 -> 100 | N19: =Pressupostos_Assumpt!C44 -> 100 | O19: =SUM(C19:N19) -> 1200
B20: Marketing+website | C20: =Pressupostos_Assumpt!C45 -> 80 | D20: =Pressupostos_Assumpt!C45 -> 80 | E20: =Pressupostos_Assumpt!C45 -> 80 | F20: =Pressupostos_Assumpt!C45 -> 80 | G20: =Pressupostos_Assumpt!C45 -> 80 | H20: =Pressupostos_Assumpt!C45 -> 80 | I20: =Pressupostos_Assumpt!C45 -> 80 | J20: =Pressupostos_Assumpt!C45 -> 80 | K20: =Pressupostos_Assumpt!C45 -> 80 | L20: =Pressupostos_Assumpt!C45 -> 80 | M20: =Pressupostos_Assumpt!C45 -> 80 | N20: =Pressupostos_Assumpt!C45 -> 80 | O20: =SUM(C20:N20) -> 960
B21: Banco+diversos / Bank+misc | C21: =Pressupostos_Assumpt!C46 -> 30 | D21: =Pressupostos_Assumpt!C46 -> 30 | E21: =Pressupostos_Assumpt!C46 -> 30 | F21: =Pressupostos_Assumpt!C46 -> 30 | G21: =Pressupostos_Assumpt!C46 -> 30 | H21: =Pressupostos_Assumpt!C46 -> 30 | I21: =Pressupostos_Assumpt!C46 -> 30 | J21: =Pressupostos_Assumpt!C46 -> 30 | K21: =Pressupostos_Assumpt!C46 -> 30 | L21: =Pressupostos_Assumpt!C46 -> 30 | M21: =Pressupostos_Assumpt!C46 -> 30 | N21: =Pressupostos_Assumpt!C46 -> 30 | O21: =SUM(C21:N21) -> 360
B22: Subtotal negocio / Subtotal overhead | C22: =C19+C20+C21 -> 210 | D22: =D19+D20+D21 -> 210 | E22: =E19+E20+E21 -> 210 | F22: =F19+F20+F21 -> 210 | G22: =G19+G20+G21 -> 210 | H22: =H19+H20+H21 -> 210 | I22: =I19+I20+I21 -> 210 | J22: =J19+J20+J21 -> 210 | ... N22: =N19+N20+N21 -> 210 | O22: =SUM(C22:N22) -> 2520
B23: NAO-CAIXA E FINANCEIRO / NON-CASH & FINANCING
B24: Depreciacao / Depreciation | C24: =Pressupostos_Assumpt!C15/12*Pressupostos_Assumpt!C50 -> 333.33333 | D24: =Pressupostos_Assumpt!C15/12*Pressupostos_Assumpt!C50 -> 333.33333 | E24: =Pressupostos_Assumpt!C15/12*Pressupostos_Assumpt!C50 -> 333.33333 | F24: =Pressupostos_Assumpt!C15/12*Pressupostos_Assumpt!C50 -> 333.33333 | G24: =Pressupostos_Assumpt!C15/12*Pressupostos_Assumpt!C50 -> 333.33333 | H24: =Pressupostos_Assumpt!C15/12*Pressupostos_Assumpt!C50 -> 333.33333 | I24: =Pressupostos_Assumpt!C15/12*Pressupostos_Assumpt!C50 -> 333.33333 | J24: =Pressupostos_Assumpt!C15/12*Pressupostos_Assumpt!C50 -> 333.33333 | K24: =Pressupostos_Assumpt!C15/12*Pressupostos_Assumpt!C50 -> 333.33333 | L24: =Pressupostos_Assumpt!C15/12*Pressupostos_Assumpt!C50 -> 333.33333 | M24: =Pressupostos_Assumpt!C15/12*Pressupostos_Assumpt!C50 -> 333.33333 | N24: =Pressupostos_Assumpt!C15/12*Pressupostos_Assumpt!C50 -> 333.33333 | O24: =SUM(C24:N24) -> 4000
B25: Juro emprestimo / Loan interest | C25: =Financiamento_Loan!D11*Pressupostos_Assumpt!C50 -> 240 | D25: =Financiamento_Loan!D12*Pressupostos_Assumpt!C50 -> 237.85931 | E25: =Financiamento_Loan!D13*Pressupostos_Assumpt!C50 -> 235.70435 | F25: =Financiamento_Loan!D14*Pressupostos_Assumpt!C50 -> 233.53502 | G25: =Financiamento_Loan!D15*Pressupostos_Assumpt!C50 -> 231.35123 | H25: =Financiamento_Loan!D16*Pressupostos_Assumpt!C50 -> 229.15288 | I25: =Financiamento_Loan!D17*Pressupostos_Assumpt!C50 -> 226.93987 | J25: =Financiamento_Loan!D18*Pressupostos_Assumpt!C50 -> 224.71211 | K25: =Financiamento_Loan!D19*Pressupostos_Assumpt!C50 -> 222.4695 | L25: =Financiamento_Loan!D20*Pressupostos_Assumpt!C50 -> 220.21194 | M25: =Financiamento_Loan!D21*Pressupostos_Assumpt!C50 -> 217.93933 | N25: =Financiamento_Loan!D22*Pressupostos_Assumpt!C50 -> 215.65156 | O25: =SUM(C25:N25) -> 2735.5271

Sheet DRE_PL
B2: DRE / P&L - Ano 1 mensal / Year 1 monthly
B3: Demonstracao de resultados / Income statement
B5: Rubrica / Item | C5: Jan | D5: Fev | E5: Mar | F5: Abr | G5: Mai | H5: Jun | I5: Jul | J5: Ago | K5: Set | L5: Out | M5: Nov | N5: Dez | O5: Total Ano 1
B6: Receita total / Total revenue | C6: =Receita_Revenue!C14 -> 464.464 | D6: =Receita_Revenue!D14 -> 416.416 | E6: =Receita_Revenue!E14 -> 464.464 | F6: =Receita_Revenue!F14 -> 1646.4 | G6: =Receita_Revenue!G14 -> 1705.2 | H6: =Receita_Revenue!H14 -> 4014.08 | I6: =Receita_Revenue!I14 -> 4157.44 | J6: =Receita_Revenue!J14 -> 4157.44 | ... N6: =Receita_Revenue!N14 -> 464.464 | O6: =SUM(C6:N6) -> 23658.096
B7: (-) Custos variaveis / Variable costs | C7: =-Custos_Costs!C9 -> -112.20293 | D7: =-Custos_Costs!D9 -> -100.59573 | E7: =-Custos_Costs!E9 -> -112.20293 | F7: =-Custos_Costs!F9 -> -340.29333 | G7: =-Custos_Costs!G9 -> -352.44667 | H7: =-Custos_Costs!H9 -> -751.44533 | I7: =-Custos_Costs!I9 -> -778.28267 | J7: =-Custos_Costs!J9 -> -778.28267 | ... N7: =-Custos_Costs!N9 -> -112.20293 | O7: =SUM(C7:N7) -> -4650.1811
B8: = Margem contribuicao / Contribution margin | C8: =C6+C7 -> 352.26107 | D8: =D6+D7 -> 315.82027 | E8: =E6+E7 -> 352.26107 | F8: =F6+F7 -> 1306.1067 | G8: =G6+G7 -> 1352.7533 | H8: =H6+H7 -> 3262.6347 | I8: =I6+I7 -> 3379.1573 | J8: =J6+J7 -> 3379.1573 | ... N8: =N6+N7 -> 352.26107 | O8: =SUM(C8:N8) -> 19007.915
B9: (-) Fixos carrinha / Per-van fixed | C9: =-Custos_Costs!C17 -> -304.16667 | D9: =-Custos_Costs!D17 -> -304.16667 | E9: =-Custos_Costs!E17 -> -304.16667 | F9: =-Custos_Costs!F17 -> -304.16667 | G9: =-Custos_Costs!G17 -> -304.16667 | H9: =-Custos_Costs!H17 -> -304.16667 | I9: =-Custos_Costs!I17 -> -304.16667 | J9: =-Custos_Costs!J17 -> -304.16667 | ... N9: =-Custos_Costs!N17 -> -304.16667 | O9: =SUM(C9:N9) -> -3650
B10: (-) Negocio / Overhead | C10: =-Custos_Costs!C22 -> -210 | D10: =-Custos_Costs!D22 -> -210 | E10: =-Custos_Costs!E22 -> -210 | F10: =-Custos_Costs!F22 -> -210 | G10: =-Custos_Costs!G22 -> -210 | H10: =-Custos_Costs!H22 -> -210 | I10: =-Custos_Costs!I22 -> -210 | J10: =-Custos_Costs!J22 -> -210 | ... N10: =-Custos_Costs!N22 -> -210 | O10: =SUM(C10:N10) -> -2520
B11: = EBITDA | C11: =C8+C9+C10 -> -161.9056 | D11: =D8+D9+D10 -> -198.3464 | E11: =E8+E9+E10 -> -161.9056 | F11: =F8+F9+F10 -> 791.94 | G11: =G8+G9+G10 -> 838.58667 | H11: =H8+H9+H10 -> 2748.468 | I11: =I8+I9+I10 -> 2864.9907 | J11: =J8+J9+J10 -> 2864.9907 | ... N11: =N8+N9+N10 -> -161.9056 | O11: =SUM(C11:N11) -> 12837.915
B12: (-) Depreciacao / Depreciation | C12: =-Custos_Costs!C24 -> -333.33333 | D12: =-Custos_Costs!D24 -> -333.33333 | E12: =-Custos_Costs!E24 -> -333.33333 | F12: =-Custos_Costs!F24 -> -333.33333 | G12: =-Custos_Costs!G24 -> -333.33333 | H12: =-Custos_Costs!H24 -> -333.33333 | I12: =-Custos_Costs!I24 -> -333.33333 | J12: =-Custos_Costs!J24 -> -333.33333 | ... N12: =-Custos_Costs!N24 -> -333.33333 | O12: =SUM(C12:N12) -> -4000
B13: = EBIT | C13: =C11+C12 -> -495.23893 | D13: =D11+D12 -> -531.67973 | E13: =E11+E12 -> -495.23893 | F13: =F11+F12 -> 458.60667 | G13: =G11+G12 -> 505.25333 | H13: =H11+H12 -> 2415.1347 | I13: =I11+I12 -> 2531.6573 | J13: =J11+J12 -> 2531.6573 | ... N13: =N11+N12 -> -495.23893 | O13: =SUM(C13:N13) -> 8837.9149
B14: (-) Juros / Interest | C14: =-Custos_Costs!C25 -> -240 | D14: =-Custos_Costs!D25 -> -237.85931 | E14: =-Custos_Costs!E25 -> -235.70435 | F14: =-Custos_Costs!F25 -> -233.53502 | G14: =-Custos_Costs!G25 -> -231.35123 | H14: =-Custos_Costs!H25 -> -229.15288 | I14: =-Custos_Costs!I25 -> -226.93987 | J14: =-Custos_Costs!J25 -> -224.71211 | ... N14: =-Custos_Costs!N25 -> -215.65156 | O14: =SUM(C14:N14) -> -2735.5271
B15: = Resultado antes impostos / EBT | C15: =C13+C14 -> -735.23893 | D15: =D13+D14 -> -769.53904 | E15: =E13+E14 -> -730.94328 | F15: =F13+F14 -> 225.07165 | G15: =G13+G14 -> 273.90211 | H15: =H13+H14 -> 2185.9818 | I15: =I13+I14 -> 2304.7175 | J15: =J13+J14 -> 2306.9452 | ... N15: =N13+N14 -> -710.8905 | O15: =SUM(C15:N15) -> 6102.3879
B16: (-) IRC / Corporate tax | C16: =-IF(C15>0,C15*Pressupostos_Assumpt!C56,0) -> 0 | D16: =-IF(D15>0,D15*Pressupostos_Assumpt!C56,0) -> 0 | E16: =-IF(E15>0,E15*Pressupostos_Assumpt!C56,0) -> 0 | F16: =-IF(F15>0,F15*Pressupostos_Assumpt!C56,0) -> -36.011464 | G16: =-IF(G15>0,G15*Pressupostos_Assumpt!C56,0) -> -43.824337 | H16: =-IF(H15>0,H15*Pressupostos_Assumpt!C56,0) -> -349.75709 | I16: =-IF(I15>0,I15*Pressupostos_Assumpt!C56,0) -> -368.75479 | J16: =-IF(J15>0,J15*Pressupostos_Assumpt!C56,0) -> -369.11124 | K16: =-IF(K15>0,K15*Pressupostos_Assumpt!C56,0) -> -350.82643 | L16: =-IF(L15>0,L15*Pressupostos_Assumpt!C56,0) -> -45.606623 | M16: =-IF(M15>0,M15*Pressupostos_Assumpt!C56,0) -> 0 | N16: =-IF(N15>0,N15*Pressupostos_Assumpt!C56,0) -> 0 | O16: =SUM(C16:N16) -> -1563.892
B17: = RESULTADO LIQUIDO / NET PROFIT | C17: =C15+C16 -> -735.23893 | D17: =D15+D16 -> -769.53904 | E17: =E15+E16 -> -730.94328 | F17: =F15+F16 -> 189.06019 | G17: =G15+G16 -> 230.07777 | H17: =H15+H16 -> 1836.2247 | I17: =I15+I16 -> 1935.9627 | J17: =J15+J16 -> 1937.834 | ... N17: =N15+N16 -> -710.8905 | O17: =SUM(C17:N17) -> 4538.4959

Sheet Resumo_Multianual
B2: RESUMO MULTIANUAL / MULTI-YEAR SUMMARY (1 carrinha, ate a venda)
B3: Ano 1 = total do plano mensal | Anos seguintes anuais | venda quando atinge o alvo km
B5: Rubrica / Item (EUR) | C5: Ano 1 (mensal) | D5: Ano 2 | E5: Ano 3 | F5: Ano 4 | G5: Ano 5 | H5: Ano 6
B6: Carrinha em operacao? / Van in service? | C6: =IF(1<=Venda_Resale!$C$27,1,0) -> 1 | D6: =IF(2<=Venda_Resale!$C$27,1,0) -> 1 | E6: =IF(3<=Venda_Resale!$C$27,1,0) -> 1 | F6: =IF(4<=Venda_Resale!$C$27,1,0) -> 1 | G6: =IF(5<=Venda_Resale!$C$27,1,0) -> 0 | H6: =IF(6<=Venda_Resale!$C$27,1,0) -> 0
B7: Receita / Revenue | C7: =Venda_Resale!C14*C6 -> 23658.096 | D7: =Venda_Resale!D14*D6 -> 24367.839 | E7: =Venda_Resale!E14*E6 -> 25098.874 | F7: =Venda_Resale!F14*F6 -> 25851.84 | G7: =Venda_Resale!G14*G6 -> 0 | H7: =Venda_Resale!H14*H6 -> 0
B8: EBITDA | C8: =Venda_Resale!C15*C6 -> 12837.915 | D8: =Venda_Resale!D15*D6 -> 13332.552 | E8: =Venda_Resale!E15*E6 -> 13842.029 | F8: =Venda_Resale!F15*F6 -> 14366.79 | G8: =Venda_Resale!G15*G6 -> 0 | H8: =Venda_Resale!H15*H6 -> 0
B9: (-) Depreciacao / Depreciation | C9: =Venda_Resale!C16*C6 -> -4000 | D9: =Venda_Resale!D16*D6 -> -4000 | E9: =Venda_Resale!E16*E6 -> -4000 | F9: =Venda_Resale!F16*F6 -> -4000 | G9: =Venda_Resale!G16*G6 -> 0 | H9: =Venda_Resale!H16*H6 -> 0
B10: (-) Juros / Interest | C10: =Venda_Resale!C17*C6 -> -2735.5271 | D10: =Venda_Resale!D17*D6 -> -2403.7185 | E10: =Venda_Resale!E17*E6 -> -2044.37 | F10: =Venda_Resale!F17*F6 -> -1655.1957 | G10: =Venda_Resale!G17*G6 -> 0 | H10: =Venda_Resale!H17*H6 -> 0
B11: = EBT | C11: =C8+C9+C10 -> 6102.3879 | D11: =D8+D9+D10 -> 6928.8339 | E11: =E8+E9+E10 -> 7797.659 | F11: =F8+F9+F10 -> 8711.5941 | G11: =G8+G9+G10 -> 0 | H11: =H8+H9+H10 -> 0
B12: (-) IRC | C12: =-IF(C11>0,C11*Pressupostos_Assumpt!C56,0) -> -976.38206 | D12: =-IF(D11>0,D11*Pressupostos_Assumpt!C56,0) -> -1108.6134 | E12: =-IF(E11>0,E11*Pressupostos_Assumpt!C56,0) -> -1247.6254 | F12: =-IF(F11>0,F11*Pressupostos_Assumpt!C56,0) -> -1393.8551 | G12: =-IF(G11>0,G11*Pressupostos_Assumpt!C56,0) -> 0 | H12: =-IF(H11>0,H11*Pressupostos_Assumpt!C56,0) -> 0
B13: = Resultado operacional / Operating profit | C13: =C11+C12 -> 5126.0058 | D13: =D11+D12 -> 5820.2205 | E13: =E11+E12 -> 6550.0336 | F13: =F11+F12 -> 7317.7391 | G13: =G11+G12 -> 0 | H13: =H11+H12 -> 0
B14: (+/-) Resultado da venda (liq. imposto) / Disposal result net | C14: =IF(1=Venda_Resale!$C$27,(Venda_Resale!C7-(Pressupostos_Assumpt!C7-Pressupostos_Assumpt!C15*MIN(1,Pressupostos_Assumpt!C13)))*(1-Pressupostos_Assumpt!C56),0) -> 0 | D14: =IF(2=Venda_Resale!$C$27,(Venda_Resale!D7-(Pressupostos_Assumpt!C7-Pressupostos_Assumpt!C15*MIN(2,Pressupostos_Assumpt!C13)))*(1-Pressupostos_Assumpt!C56),0) -> 0 | E14: =IF(3=Venda_Resale!$C$27,(Venda_Resale!E7-(Pressupostos_Assumpt!C7-Pressupostos_Assumpt!C15*MIN(3,Pressupostos_Assumpt!C13)))*(1-Pressupostos_Assumpt!C56),0) -> 0 | F14: =IF(4=Venda_Resale!$C$27,(Venda_Resale!F7-(Pressupostos_Assumpt!C7-Pressupostos_Assumpt!C15*MIN(4,Pressupostos_Assumpt!C13)))*(1-Pressupostos_Assumpt!C56),0) -> -3681.6192 | G14: =IF(5=Venda_Resale!$C$27,(Venda_Resale!G7-(Pressupostos_Assumpt!C7-Pressupostos_Assumpt!C15*MIN(5,Pressupostos_Assumpt!C13)))*(1-Pressupostos_Assumpt!C56),0) -> 0 | H14: =IF(6=Venda_Resale!$C$27,(Venda_Resale!H7-(Pressupostos_Assumpt!C7-Pressupostos_Assumpt!C15*MIN(6,Pressupostos_Assumpt!C13)))*(1-Pressupostos_Assumpt!C56),0) -> 0
B15: = RESULTADO TOTAL / TOTAL RESULT | C15: =C13+C14 -> 5126.0058 | D15: =D13+D14 -> 5820.2205 | E15: =E13+E14 -> 6550.0336 | F15: =F13+F14 -> 3636.1199 | G15: =G13+G14 -> 0 | H15: =H13+H14 -> 0
B17: CAIXA / CASH
B18: Caixa gerada no ano / Cash generated in year | C18: =Tesouraria_CashFlow!N17 -> 12540.778 | D18: =D8+D12-12*Financiamento_Loan!$C$8*D6+IF(2=Venda_Resale!$C$27,Venda_Resale!$C$34,0) -> 5490.6943 | E18: =E8+E12-12*Financiamento_Loan!$C$8*E6+IF(3=Venda_Resale!$C$27,Venda_Resale!$C$34,0) -> 5861.1589 | F18: =F8+F12-12*Financiamento_Loan!$C$8*F6+IF(4=Venda_Resale!$C$27,Venda_Resale!$C$34,0) -> 8652.2382 | G18: =G8+G12-12*Financiamento_Loan!$C$8*G6+IF(5=Venda_Resale!$C$27,Venda_Resale!$C$34,0) -> 0 | H18: =H8+H12-12*Financiamento_Loan!$C$8*H6+IF(6=Venda_Resale!$C$27,Venda_Resale!$C$34,0) -> 0
B19: Caixa acumulada / Cumulative cash | C19: =C18 -> 12540.778 | D19: =C19+D18 -> 18031.473 | E19: =D19+E18 -> 23892.632 | F19: =E19+F18 -> 32544.87 | G19: =F19+G18 -> 32544.87 | H19: =G19+H18 -> 32544.87
B21: BALANCO DA OPERACAO / LIFETIME SUMMARY
B22: Ano da venda / Year of sale | C22: =Venda_Resale!$C$27 -> 4
B23: Lucro operacional acumulado / Cumulative operating profit | C23: =SUMIF(C6:H6,1,C13:H13) -> 24813.999
B24: (+/-) Resultado da venda (liq.) / Disposal result net | C24: =INDEX(C14:H14,Venda_Resale!$C$27) -> -3681.6192
B25: = LUCRO TOTAL (alugueres+venda) / TOTAL PROFIT (rentals+sale) | C25: =Venda_Resale!$C$36 -> 21132.38
B26: Caixa acumulada final (inclui capital proprio) / Final cash | C26: =INDEX(C19:H19,Venda_Resale!$C$27) -> 32544.87
B27: (+) Caixa dos alugueres / Rental cash | C27: =INDEX(Venda_Resale!C42:I42,Venda_Resale!$C$27) -> 49652.81
B28: (+) Venda da carrinha / Sale of the van | C28: =INDEX(Venda_Resale!C43:I43,Venda_Resale!$C$27) -> 19617.12
B29: (-) Custo da carrinha (compra+juros) / Van cost | C29: =INDEX(Venda_Resale!C44:I44,Venda_Resale!$C$27) -> -48838.811
B30: = GANHO TOTAL DE CAIXA / TOTAL CASH GAIN | C30: =INDEX(Venda_Resale!C45:I45,Venda_Resale!$C$27) -> 20431.119
B32: Nota: a carrinha e vendida no ano em que atinge o alvo de km; depois a operacao para.
B33: Note: van is sold the year it hits the target km; operations stop afterwards. Edit km/day or target in Assumptions.
B35: RETORNO DO INVESTIMENTO / RETURN ON INVESTMENT (dinheiro real)
B36: Fim do ano / End of year | C36: Ano 1 | D36: Ano 2 | E36: Ano 3 | F36: Ano 4 | G36: Ano 5 | H36: Ano 6
B37: Dinheiro da empresa / Company cash | C37: =C19 -> 12540.778 | D37: =D19 -> 18031.473 | E37: =E19 -> 23892.632 | F37: =F19 -> 32544.87 | G37: =G19 -> 32544.87 | H37: =H19 -> 32544.87
B38: x investimento inicial / x initial investment | C38: =C37/Pressupostos_Assumpt!C51 -> 1.0450649 | D38: =D37/Pressupostos_Assumpt!C51 -> 1.5026227 | E38: =E37/Pressupostos_Assumpt!C51 -> 1.9910526 | F38: =F37/Pressupostos_Assumpt!C51 -> 2.7120725 | G38: =G37/Pressupostos_Assumpt!C51 -> 2.7120725 | H38: =H37/Pressupostos_Assumpt!C51 -> 2.7120725
B39: Crescimento acumulado / Cumulative growth | C39: =(C37-Pressupostos_Assumpt!C51)/Pressupostos_Assumpt!C51 -> 0.045064862 | D39: =(D37-Pressupostos_Assumpt!C51)/Pressupostos_Assumpt!C51 -> 0.50262272 | E39: =(E37-Pressupostos_Assumpt!C51)/Pressupostos_Assumpt!C51 -> 0.99105263 | F39: =(F37-Pressupostos_Assumpt!C51)/Pressupostos_Assumpt!C51 -> 1.7120725 | G39: =(G37-Pressupostos_Assumpt!C51)/Pressupostos_Assumpt!C51 -> 1.7120725 | H39: =(H37-Pressupostos_Assumpt!C51)/Pressupostos_Assumpt!C51 -> 1.7120725
B41: Fluxo para o investidor / Investor cash flow
B42: Ano / Year | C42: 0 | D42: 1 | E42: 2 | F42: 3 | G42: 4 | H42: 5 | I42: 6
B43: Entradas/saidas de caixa / Cash in/out | C43: =-Pressupostos_Assumpt!C51 -> -12000 | D43: =C37-Pressupostos_Assumpt!C51 -> 540.77834 | E43: =D37-C37 -> 5490.6943 | F43: =E37-D37 -> 5861.1589 | G43: =F37-E37 -> 8652.2382 | H43: =G37-F37 -> 0 | I43: =H37-G37 -> 0
B45: Investimento inicial / Initial investment | C45: =Pressupostos_Assumpt!C51 -> 12000
B46: Dinheiro no fim (ano da venda) / Money at the end | C46: =INDEX(C37:H37,Venda_Resale!$C$27) -> 32544.87
B47: Ganho liquido / Net gain | C47: =INDEX(C37:H37,Venda_Resale!$C$27)-Pressupostos_Assumpt!C51 -> 20544.87
B48: Multiplo do investimento / Money multiple | C48: =INDEX(C37:H37,Venda_Resale!$C$27)/Pressupostos_Assumpt!C51 -> 2.7120725
...

Sheet Tesouraria_CashFlow
B2: TESOURARIA / CASH FLOW - Ano 1 mensal / Year 1 monthly
B3: Inclui IVA, financiamento e capital / Incl. VAT, financing & capital
B5: Rubrica / Item | C5: Jan | D5: Fev | E5: Mar | F5: Abr | G5: Mai | H5: Jun | I5: Jul | J5: Ago | K5: Set | L5: Out | M5: Nov | N5: Dez | O5: Total Ano 1
B6: IVA liquidado (info) / Output VAT | C6: =Receita_Revenue!C14*Pressupostos_Assumpt!C54 -> 106.82672 | D6: =Receita_Revenue!D14*Pressupostos_Assumpt!C54 -> 95.77568 | E6: =Receita_Revenue!E14*Pressupostos_Assumpt!C54 -> 106.82672 | F6: =Receita_Revenue!F14*Pressupostos_Assumpt!C54 -> 378.672 | G6: =Receita_Revenue!G14*Pressupostos_Assumpt!C54 -> 392.196 | H6: =Receita_Revenue!H14*Pressupostos_Assumpt!C54 -> 923.2384 | I6: =Receita_Revenue!I14*Pressupostos_Assumpt!C54 -> 956.2112 | J6: =Receita_Revenue!J14*Pressupostos_Assumpt!C54 -> 956.2112 | K6: =Receita_Revenue!K14*Pressupostos_Assumpt!C54 -> 923.2384 | L6: =Receita_Revenue!L14*Pressupostos_Assumpt!C54 -> 392.196 | M6: =Receita_Revenue!M14*Pressupostos_Assumpt!C54 -> 103.14304 | N6: =Receita_Revenue!N14*Pressupostos_Assumpt!C54 -> 106.82672 | O6: =SUM(C6:N6) -> 5441.3621
B7: IVA dedutivel (info) / Input VAT | C7: =(Custos_Costs!C7+Custos_Costs!C8+Custos_Costs!C12+Custos_Costs!C13+Custos_Costs!C19+Custos_Costs!C20)*Pressupostos_Assumpt!C54*Pressupostos_Assumpt!C55 -> 94.806675 | D7: =(Custos_Costs!D7+Custos_Costs!D8+Custos_Costs!D12+Custos_Costs!D13+Custos_Costs!D19+Custos_Costs!D20)*Pressupostos_Assumpt!C54*Pressupostos_Assumpt!C55 -> 92.137019 | E7: =(Custos_Costs!E7+Custos_Costs!E8+Custos_Costs!E12+Custos_Costs!E13+Custos_Costs!E19+Custos_Costs!E20)*Pressupostos_Assumpt!C54*Pressupostos_Assumpt!C55 -> 94.806675 | F7: =(Custos_Costs!F7+Custos_Costs!F8+Custos_Costs!F12+Custos_Costs!F13+Custos_Costs!F19+Custos_Costs!F20)*Pressupostos_Assumpt!C54*Pressupostos_Assumpt!C55 -> 147.26747 | G7: =(Custos_Costs!G7+Custos_Costs!G8+Custos_Costs!G12+Custos_Costs!G13+Custos_Costs!G19+Custos_Costs!G20)*Pressupostos_Assumpt!C54*Pressupostos_Assumpt!C55 -> 150.06273 | H7: =(Custos_Costs!H7+Custos_Costs!H8+Custos_Costs!H12+Custos_Costs!H13+Custos_Costs!H19+Custos_Costs!H20)*Pressupostos_Assumpt!C54*Pressupostos_Assumpt!C55 -> 241.83243 | I7: =(Custos_Costs!I7+Custos_Costs!I8+Custos_Costs!I12+Custos_Costs!I13+Custos_Costs!I19+Custos_Costs!I20)*Pressupostos_Assumpt!C54*Pressupostos_Assumpt!C55 -> 248.00501 | J7: =(Custos_Costs!J7+Custos_Costs!J8+Custos_Costs!J12+Custos_Costs!J13+Custos_Costs!J19+Custos_Costs!J20)*Pressupostos_Assumpt!C54*Pressupostos_Assumpt!C55 -> 248.00501 | K7: =(Custos_Costs!K7+Custos_Costs!K8+Custos_Costs!K12+Custos_Costs!K13+Custos_Costs!K19+Custos_Costs!K20)*Pressupostos_Assumpt!C54*Pressupostos_Assumpt!C55 -> 241.83243 | L7: =(Custos_Costs!L7+Custos_Costs!L8+Custos_Costs!L12+Custos_Costs!L13+Custos_Costs!L19+Custos_Costs!L20)*Pressupostos_Assumpt!C54*Pressupostos_Assumpt!C55 -> 150.06273 | M7: =(Custos_Costs!M7+Custos_Costs!M8+Custos_Costs!M12+Custos_Costs!M13+Custos_Costs!M19+Custos_Costs!M20)*Pressupostos_Assumpt!C54*Pressupostos_Assumpt!C55 -> 93.916789 | N7: =(Custos_Costs!N7+Custos_Costs!N8+Custos_Costs!N12+Custos_Costs!N13+Custos_Costs!N19+Custos_Costs!N20)*Pressupostos_Assumpt!C54*Pressupostos_Assumpt!C55 -> 94.806675 | O7: =SUM(C7:N7) -> 1897.5416
B8: FLUXOS DE CAIXA / CASH FLOWS
B9: (+) Capital inicial / Initial capital | C9: =Pressupostos_Assumpt!C51 -> 12000 | D9: 0 | E9: 0 | F9: 0 | G9: 0 | H9: 0 | I9: 0 | J9: 0 | K9: 0 | L9: 0 | M9: 0 | N9: 0 | O9: =SUM(C9:N9) -> 12000
B10: (+) Recebimentos (c/ IVA) / Receipts incl. VAT | C10: =Receita_Revenue!C14*(1+Pressupostos_Assumpt!C54) -> 571.29072 | D10: =Receita_Revenue!D14*(1+Pressupostos_Assumpt!C54) -> 512.19168 | E10: =Receita_Revenue!E14*(1+Pressupostos_Assumpt!C54) -> 571.29072 | F10: =Receita_Revenue!F14*(1+Pressupostos_Assumpt!C54) -> 2025.072 | G10: =Receita_Revenue!G14*(1+Pressupostos_Assumpt!C54) -> 2097.396 | H10: =Receita_Revenue!H14*(1+Pressupostos_Assumpt!C54) -> 4937.3184 | I10: =Receita_Revenue!I14*(1+Pressupostos_Assumpt!C54) -> 5113.6512 | J10: =Receita_Revenue!J14*(1+Pressupostos_Assumpt!C54) -> 5113.6512 | K10: =Receita_Revenue!K14*(1+Pressupostos_Assumpt!C54) -> 4937.3184 | L10: =Receita_Revenue!L14*(1+Pressupostos_Assumpt!C54) -> 2097.396 | M10: =Receita_Revenue!M14*(1+Pressupostos_Assumpt!C54) -> 551.59104 | N10: =Receita_Revenue!N14*(1+Pressupostos_Assumpt!C54) -> 571.29072 | O10: =SUM(C10:N10) -> 29099.458
B11: (-) Pagamentos op. (c/ IVA) / Op. payments incl. VAT | C11: =-((Custos_Costs!C9+Custos_Costs!C12+Custos_Costs!C13+Custos_Costs!C19+Custos_Costs!C20)*(1+Pressupostos_Assumpt!C54)+Custos_Costs!C25*0+(Pressupostos_Assumpt!C36*Pressupostos_Assumpt!C50+Pressupostos_Assumpt!C39/12*Pressupostos_Assumpt!C50+Pressupostos_Assumpt!C40/12*Pressupostos_Assumpt!C50+Pressupostos_Assumpt!C41/12*Pressupostos_Assumpt!C50+Pressupostos_Assumpt!C46)) -> -721.17627 | D11: =-((Custos_Costs!D9+Custos_Costs!D12+Custos_Costs!D13+Custos_Costs!D19+Custos_Costs!D20)*(1+Pressupostos_Assumpt!C54)+Custos_Costs!D25*0+(Pressupostos_Assumpt!C36*Pressupostos_Assumpt!C50+Pressupostos_Assumpt!C39/12*Pressupostos_Assumpt!C50+Pressupostos_Assumpt!C40/12*Pressupostos_Assumpt!C50+Pressupostos_Assumpt!C41/12*Pressupostos_Assumpt!C50+Pressupostos_Assumpt!C46)) -> -706.89942 | E11: =-((Custos_Costs!E9+Custos_Costs!E12+Custos_Costs!E13+Custos_Costs!E19+Custos_Costs!E20)*(1+Pressupostos_Assumpt!C54)+Custos_Costs!E25*0+(Pressupostos_Assumpt!C36*Pressupostos_Assumpt!C50+Pressupostos_Assumpt!C39/12*Pressupostos_Assumpt!C50+Pressupostos_Assumpt!C40/12*Pressupostos_Assumpt!C50+Pressupostos_Assumpt!C41/12*Pressupostos_Assumpt!C50+Pressupostos_Assumpt!C46)) -> -721.17627 | F11: =-((Custos_Costs!F9+Custos_Costs!F12+Custos_Costs!F13+Custos_Costs!F19+Custos_Costs!F20)*(1+Pressupostos_Assumpt!C54)+Custos_Costs!F25*0+(Pressupostos_Assumpt!C36*Pressupostos_Assumpt!C50+Pressupostos_Assumpt!C39/12*Pressupostos_Assumpt!C50+Pressupostos_Assumpt!C40/12*Pressupostos_Assumpt!C50+Pressupostos_Assumpt!C41/12*Pressupostos_Assumpt!C50+Pressupostos_Assumpt!C46)) -> -1001.7275 | G11: =-((Custos_Costs!G9+Custos_Costs!G12+Custos_Costs!G13+Custos_Costs!G19+Custos_Costs!G20)*(1+Pressupostos_Assumpt!C54)+Custos_Costs!G25*0+(Pressupostos_Assumpt!C36*Pressupostos_Assumpt!C50+Pressupostos_Assumpt!C39/12*Pressupostos_Assumpt!C50+Pressupostos_Assumpt!C40/12*Pressupostos_Assumpt!C50+Pressupostos_Assumpt!C41/12*Pressupostos_Assumpt!C50+Pressupostos_Assumpt!C46)) -> -1016.6761 | H11: =-((Custos_Costs!H9+Custos_Costs!H12+Custos_Costs!H13+Custos_Costs!H19+Custos_Costs!H20)*(1+Pressupostos_Assumpt!C54)+Custos_Costs!H25*0+(Pressupostos_Assumpt!C36*Pressupostos_Assumpt!C50+Pressupostos_Assumpt!C39/12*Pressupostos_Assumpt!C50+Pressupostos_Assumpt!C40/12*Pressupostos_Assumpt!C50+Pressupostos_Assumpt!C41/12*Pressupostos_Assumpt!C50+Pressupostos_Assumpt!C46)) -> -1507.4444 | I11: =-((Custos_Costs!I9+Custos_Costs!I12+Custos_Costs!I13+Custos_Costs!I19+Custos_Costs!I20)*(1+Pressupostos_Assumpt!C54)+Custos_Costs!I25*0+(Pressupostos_Assumpt!C36*Pressupostos_Assumpt!C50+Pressupostos_Assumpt!C39/12*Pressupostos_Assumpt!C50+Pressupostos_Assumpt!C40/12*Pressupostos_Assumpt!C50+Pressupostos_Assumpt!C41/12*Pressupostos_Assumpt!C50+Pressupostos_Assumpt!C46)) -> -1540.4543 | J11: =-((Custos_Costs!J9+Custos_Costs!J12+Custos_Costs!J13+Custos_Costs!J19+Custos_Costs!J20)*(1+Pressupostos_Assumpt!C54)+Custos_Costs!J25*0+(Pressupostos_Assumpt!C36*Pressupostos_Assumpt!C50+Pressupostos_Assumpt!C39/12*Pressupostos_Assumpt!C50+Pressupostos_Assumpt!C40/12*Pressupostos_Assumpt!C50+Pressupostos_Assumpt!C41/12*Pressupostos_Assumpt!C50+Pressupostos_Assumpt!C46)) -> -1540.4543 | K11: =-((Custos_Costs!K9+Custos_Costs!K12+Custos_Costs!K13+Custos_Costs!K19+Custos_Costs!K20)*(1+Pressupostos_Assumpt!C54)+Custos_Costs!K25*0+(Pressupostos_Assumpt!C36*Pressupostos_Assumpt!C50+Pressupostos_Assumpt!C39/12*Pressupostos_Assumpt!C50+Pressupostos_Assumpt!C40/12*Pressupostos_Assumpt!C50+Pressupostos_Assumpt!C41/12*Pressupostos_Assumpt!C50+Pressupostos_Assumpt!C46)) -> -1507.4444 | L11: =-((Custos_Costs!L9+Custos_Costs!L12+Custos_Costs!L13+Custos_Costs!L19+Custos_Costs!L20)*(1+Pressupostos_Assumpt!C54)+Custos_Costs!L25*0+(Pressupostos_Assumpt!C36*Pressupostos_Assumpt!C50+Pressupostos_Assumpt!C39/12*Pressupostos_Assumpt!C50+Pressupostos_Assumpt!C40/12*Pressupostos_Assumpt!C50+Pressupostos_Assumpt!C41/12*Pressupostos_Assumpt!C50+Pressupostos_Assumpt!C46)) -> -1016.6761 | M11: =-((Custos_Costs!M9+Custos_Costs!M12+Custos_Costs!M13+Custos_Costs!M19+Custos_Costs!M20)*(1+Pressupostos_Assumpt!C54)+Custos_Costs!M25*0+(Pressupostos_Assumpt!C36*Pressupostos_Assumpt!C50+Pressupostos_Assumpt!C39/12*Pressupostos_Assumpt!C50+Pressupostos_Assumpt!C40/12*Pressupostos_Assumpt!C50+Pressupostos_Assumpt!C41/12*Pressupostos_Assumpt!C50+Pressupostos_Assumpt!C46)) -> -716.41732 | N11: =-((Custos_Costs!N9+Custos_Costs!N12+Custos_Costs!N13+Custos_Costs!N19+Custos_Costs!N20)*(1+Pressupostos_Assumpt!C54)+Custos_Costs!N25*0+(Pressupostos_Assumpt!C36*Pressupostos_Assumpt!C50+Pressupostos_Assumpt!C39/12*Pressupostos_Assumpt!C50+Pressupostos_Assumpt!C40/12*Pressupostos_Assumpt!C50+Pressupostos_Assumpt!C41/12*Pressupostos_Assumpt!C50+Pressupostos_Assumpt!C46)) -> -721.17627 | O11: =SUM(C11:N11) -> -12717.723
B12: (-) Entrada compra / Down payment | C12: =-Pressupostos_Assumpt!C10*Pressupostos_Assumpt!C50 -> -4000 | D12: 0 | E12: 0 | F12: 0 | G12: 0 | H12: 0 | I12: 0 | J12: 0 | K12: 0 | L12: 0 | M12: 0 | N12: 0 | O12: =SUM(C12:N12) -> -4000
B13: (-) Prestacao credito / Loan instalment | C13: =-Financiamento_Loan!D11*Pressupostos_Assumpt!C50-Financiamento_Loan!E11*Pressupostos_Assumpt!C50 -> -561.10372 | D13: =-Financiamento_Loan!D12*Pressupostos_Assumpt!C50-Financiamento_Loan!E12*Pressupostos_Assumpt!C50 -> -561.10372 | E13: =-Financiamento_Loan!D13*Pressupostos_Assumpt!C50-Financiamento_Loan!E13*Pressupostos_Assumpt!C50 -> -561.10372 | F13: =-Financiamento_Loan!D14*Pressupostos_Assumpt!C50-Financiamento_Loan!E14*Pressupostos_Assumpt!C50 -> -561.10372 | G13: =-Financiamento_Loan!D15*Pressupostos_Assumpt!C50-Financiamento_Loan!E15*Pressupostos_Assumpt!C50 -> -561.10372 | H13: =-Financiamento_Loan!D16*Pressupostos_Assumpt!C50-Financiamento_Loan!E16*Pressupostos_Assumpt!C50 -> -561.10372 | I13: =-Financiamento_Loan!D17*Pressupostos_Assumpt!C50-Financiamento_Loan!E17*Pressupostos_Assumpt!C50 -> -561.10372 | J13: =-Financiamento_Loan!D18*Pressupostos_Assumpt!C50-Financiamento_Loan!E18*Pressupostos_Assumpt!C50 -> -561.10372 | K13: =-Financiamento_Loan!D19*Pressupostos_Assumpt!C50-Financiamento_Loan!E19*Pressupostos_Assumpt!C50 -> -561.10372 | L13: =-Financiamento_Loan!D20*Pressupostos_Assumpt!C50-Financiamento_Loan!E20*Pressupostos_Assumpt!C50 -> -561.10372 | M13: =-Financiamento_Loan!D21*Pressupostos_Assumpt!C50-Financiamento_Loan!E21*Pressupostos_Assumpt!C50 -> -561.10372 | N13: =-Financiamento_Loan!D22*Pressupostos_Assumpt!C50-Financiamento_Loan!E22*Pressupostos_Assumpt!C50 -> -561.10372 | O13: =SUM(C13:N13) -> -6733.2446
B14: (-) Acerto IVA (trim.) / VAT settlement (qtr) | C14: 0 | D14: 0 | E14: =-(SUM(C6:E6)-SUM(C7:E7)) -> -27.678752 | F14: 0 | G14: 0 | H14: =-(SUM(F6:H6)-SUM(F7:H7)) -> -1154.9438 | I14: 0 | J14: 0 | K14: =-(SUM(I6:K6)-SUM(I7:K7)) -> -2097.8183 | L14: 0 | M14: 0 | N14: =-(SUM(L6:N6)-SUM(L7:N7)) -> -263.37956 | O14: =SUM(C14:N14) -> -3543.8204
B15: (-) IRC (pago em Dez) / Tax paid (Dec) | C15: 0 | D15: 0 | E15: 0 | F15: 0 | G15: 0 | H15: 0 | I15: 0 | J15: 0 | K15: 0 | L15: 0 | M15: 0 | N15: =DRE_PL!O16 -> -1563.892 | O15: =SUM(C15:N15) -> -1563.892
B16: = Fluxo liquido / Net cash flow | C16: =C9+C10+C11+C12+C13+C14+C15 -> 7289.0107 | D16: =D9+D10+D11+D12+D13+D14+D15 -> -755.81146 | E16: =E9+E10+E11+E12+E13+E14+E15 -> -738.66803 | F16: =F9+F10+F11+F12+F13+F14+F15 -> 462.24081 | G16: =G9+G10+G11+G12+G13+G14+G15 -> 519.61621 | H16: =H9+H10+H11+H12+H13+H14+H15 -> 1713.8265 | I16: =I9+I10+I11+I12+I13+I14+I15 -> 3012.0931 | J16: =J9+J10+J11+J12+J13+J14+J15 -> 3012.0931 | ... N16: =N9+N10+N11+N12+N13+N14+N15 -> -2538.2608 | O16: =SUM(C16:N16) -> 12540.778
B17: Saldo acumulado / Cumulative balance | C17: =C16 -> 7289.0107 | D17: =C17+D16 -> 6533.1993 | E17: =D17+E16 -> 5794.5312 | F17: =E17+F16 -> 6256.7721 | G17: =F17+G16 -> 6776.3883 | H17: =G17+H16 -> 8490.2148 | I17: =H17+I16 -> 11502.308 | J17: =I17+J16 -> 14514.401 | K17: =J17+K16 -> 15285.353 | ... N17: =M17+N16 -> 12540.778

Sheet PontoCritico_BreakEven
B2: PONTO CRITICO / BREAK-EVEN (Ano 1, 1 carrinha)
B3: Quantos dias alugados para nao ter prejuizo / Rented days to break even
B5: Preco medio/dia / Avg daily rate | C5: =Receita_Revenue!O12/Receita_Revenue!O11 -> 127.84953 | D5: EUR/dia | E5: Receita aluguer / dias alugados
B6: Margem contribuicao por dia alugado / Contribution per rented day | C6: =C5*(1+Pressupostos_Assumpt!C29)*(1-Pressupostos_Assumpt!C30)-Pressupostos_Assumpt!C32/Pressupostos_Assumpt!C31 -> 115.04609 | D6: EUR/dia | E6: Preco x extras x (1-comissao) - limpeza/dia
B7: Custos fixos anuais / Annual fixed costs | C7: =Custos_Costs!O17+Custos_Costs!O22+Custos_Costs!O24+Custos_Costs!O25 -> 12905.527 | D7: EUR/ano | E7: Fixos carrinha + negocio + deprec. + juros
B8: PONTO CRITICO - dias alugados / BREAK-EVEN rented days | C8: =C7/C6 -> 112.17702 | D8: dias/ano | E8: Fixos / margem por dia
B9: Dias alugados previstos / Forecast rented days | C9: =Receita_Revenue!O11 -> 165.22 | D9: dias/ano | E9: Do plano (Receita)
B10: Ocupacao critica / Break-even occupancy | C10: =C8/Receita_Revenue!O8 -> 0.32896486 | D10: % | E10: Dias criticos / dias disponiveis
B11: Folga / Margin of safety | C11: =(C9-C8)/C9 -> 0.32104457 | D11: % | E11: (previsto-critico)/previsto

Sheet Sensibilidades
B2: ANALISE DE SENSIBILIDADE / SENSITIVITY
B3: Resultado liquido Ano 1 (EUR) vs ocupacao e preco / Net profit Y1 vs occupancy & price
B5: Base aluguer Ano 1 / Base rental rev | C5: =Receita_Revenue!O12 -> 21123.3
B6: Base reservas Ano 1 / Base bookings | C6: =Receita_Revenue!O15 -> 27.536667
B7: Fixos+deprec.+juros / Fixed+dep+int | C7: =Custos_Costs!O17+Custos_Costs!O22+Custos_Costs!O24+Custos_Costs!O25 -> 12905.527
D9: PRECO / PRICE (fator)
B10: Lucro Ano 1 -> / Net Y1 | C10: 0.85 | D10: 0.925 | E10: 1 | F10: 1.075 | G10: 1.15
B11: 0.7 | C11: =(($C$5*C10*B11*(1+Pressupostos_Assumpt!C29))-(($C$5*C10*B11*(1+Pressupostos_Assumpt!C29))*Pressupostos_Assumpt!C30+$C$6*B11*Pressupostos_Assumpt!C32)-$C$7)-IF((($C$5*C10*B11*(1+Pressupostos_Assumpt!C29))-(($C$5*C10*B11*(1+Pressupostos_Assumpt!C29))*Pressupostos_Assumpt!C30+$C$6*B11*Pressupostos_Assumpt!C32)-$C$7)>0,(($C$5*C10*B11*(1+Pressupostos_Assumpt!C29))-(($C$5*C10*B11*(1+Pressupostos_Assumpt!C29))*Pressupostos_Assumpt!C30+$C$6*B11*Pressupostos_Assumpt!C32)-$C$7)*Pressupostos_Assumpt!C56,0) -> -1711.4717 | D11: =(($C$5*D10*B11*(1+Pressupostos_Assumpt!C29))-(($C$5*D10*B11*(1+Pressupostos_Assumpt!C29))*Pressupostos_Assumpt!C30+$C$6*B11*Pressupostos_Assumpt!C32)-$C$7)-IF((($C$5*D10*B11*(1+Pressupostos_Assumpt!C29))-(($C$5*D10*B11*(1+Pressupostos_Assumpt!C29))*Pressupostos_Assumpt!C30+$C$6*B11*Pressupostos_Assumpt!C32)-$C$7)>0,(($C$5*D10*B11*(1+Pressupostos_Assumpt!C29))-(($C$5*D10*B11*(1+Pressupostos_Assumpt!C29))*Pressupostos_Assumpt!C30+$C$6*B11*Pressupostos_Assumpt!C32)-$C$7)*Pressupostos_Assumpt!C56,0) -> -655.72916 | E11: =(($C$5*E10*B11*(1+Pressupostos_Assumpt!C29))-(($C$5*E10*B11*(1+Pressupostos_Assumpt!C29))*Pressupostos_Assumpt!C30+$C$6*B11*Pressupostos_Assumpt!C32)-$C$7)-IF((($C$5*E10*B11*(1+Pressupostos_Assumpt!C29))-(($C$5*E10*B11*(1+Pressupostos_Assumpt!C29))*Pressupostos_Assumpt!C30+$C$6*B11*Pressupostos_Assumpt!C32)-$C$7)>0,(($C$5*E10*B11*(1+Pressupostos_Assumpt!C29))-(($C$5*E10*B11*(1+Pressupostos_Assumpt!C29))*Pressupostos_Assumpt!C30+$C$6*B11*Pressupostos_Assumpt!C32)-$C$7)*Pressupostos_Assumpt!C56,0) -> 336.01123 | F11: =(($C$5*F10*B11*(1+Pressupostos_Assumpt!C29))-(($C$5*F10*B11*(1+Pressupostos_Assumpt!C29))*Pressupostos_Assumpt!C30+$C$6*B11*Pressupostos_Assumpt!C32)-$C$7)-IF((($C$5*F10*B11*(1+Pressupostos_Assumpt!C29))-(($C$5*F10*B11*(1+Pressupostos_Assumpt!C29))*Pressupostos_Assumpt!C30+$C$6*B11*Pressupostos_Assumpt!C32)-$C$7)>0,(($C$5*F10*B11*(1+Pressupostos_Assumpt!C29))-(($C$5*F10*B11*(1+Pressupostos_Assumpt!C29))*Pressupostos_Assumpt!C30+$C$6*B11*Pressupostos_Assumpt!C32)-$C$7)*Pressupostos_Assumpt!C56,0) -> 1222.835 | G11: =(($C$5*G10*B11*(1+Pressupostos_Assumpt!C29))-(($C$5*G10*B11*(1+Pressupostos_Assumpt!C29))*Pressupostos_Assumpt!C30+$C$6*B11*Pressupostos_Assumpt!C32)-$C$7)-IF((($C$5*G10*B11*(1+Pressupostos_Assumpt!C29))-(($C$5*G10*B11*(1+Pressupostos_Assumpt!C29))*Pressupostos_Assumpt!C30+$C$6*B11*Pressupostos_Assumpt!C32)-$C$7)>0,(($C$5*G10*B11*(1+Pressupostos_Assumpt!C29))-(($C$5*G10*B11*(1+Pressupostos_Assumpt!C29))*Pressupostos_Assumpt!C30+$C$6*B11*Pressupostos_Assumpt!C32)-$C$7)*Pressupostos_Assumpt!C56,0) -> 2109.6587
B12: 0.85 | C12: =(($C$5*C10*B12*(1+Pressupostos_Assumpt!C29))-(($C$5*C10*B12*(1+Pressupostos_Assumpt!C29))*Pressupostos_Assumpt!C30+$C$6*B12*Pressupostos_Assumpt!C32)-$C$7)-IF((($C$5*C10*B12*(1+Pressupostos_Assumpt!C29))-(($C$5*C10*B12*(1+Pressupostos_Assumpt!C29))*Pressupostos_Assumpt!C30+$C$6*B12*Pressupostos_Assumpt!C32)-$C$7)>0,(($C$5*C10*B12*(1+Pressupostos_Assumpt!C29))-(($C$5*C10*B12*(1+Pressupostos_Assumpt!C29))*Pressupostos_Assumpt!C30+$C$6*B12*Pressupostos_Assumpt!C32)-$C$7)*Pressupostos_Assumpt!C56,0) -> 577.29374 | D12: =(($C$5*D10*B12*(1+Pressupostos_Assumpt!C29))-(($C$5*D10*B12*(1+Pressupostos_Assumpt!C29))*Pressupostos_Assumpt!C30+$C$6*B12*Pressupostos_Assumpt!C32)-$C$7)-IF((($C$5*D10*B12*(1+Pressupostos_Assumpt!C29))-(($C$5*D10*B12*(1+Pressupostos_Assumpt!C29))*Pressupostos_Assumpt!C30+$C$6*B12*Pressupostos_Assumpt!C32)-$C$7)>0,(($C$5*D10*B12*(1+Pressupostos_Assumpt!C29))-(($C$5*D10*B12*(1+Pressupostos_Assumpt!C29))*Pressupostos_Assumpt!C30+$C$6*B12*Pressupostos_Assumpt!C32)-$C$7)*Pressupostos_Assumpt!C56,0) -> 1654.1511 | E12: =(($C$5*E10*B12*(1+Pressupostos_Assumpt!C29))-(($C$5*E10*B12*(1+Pressupostos_Assumpt!C29))*Pressupostos_Assumpt!C30+$C$6*B12*Pressupostos_Assumpt!C32)-$C$7)-IF((($C$5*E10*B12*(1+Pressupostos_Assumpt!C29))-(($C$5*E10*B12*(1+Pressupostos_Assumpt!C29))*Pressupostos_Assumpt!C30+$C$6*B12*Pressupostos_Assumpt!C32)-$C$7)>0,(($C$5*E10*B12*(1+Pressupostos_Assumpt!C29))-(($C$5*E10*B12*(1+Pressupostos_Assumpt!C29))*Pressupostos_Assumpt!C30+$C$6*B12*Pressupostos_Assumpt!C32)-$C$7)*Pressupostos_Assumpt!C56,0) -> 2731.0085 | F12: =(($C$5*F10*B12*(1+Pressupostos_Assumpt!C29))-(($C$5*F10*B12*(1+Pressupostos_Assumpt!C29))*Pressupostos_Assumpt!C30+$C$6*B12*Pressupostos_Assumpt!C32)-$C$7)-IF((($C$5*F10*B12*(1+Pressupostos_Assumpt!C29))-(($C$5*F10*B12*(1+Pressupostos_Assumpt!C29))*Pressupostos_Assumpt!C30+$C$6*B12*Pressupostos_Assumpt!C32)-$C$7)>0,(($C$5*F10*B12*(1+Pressupostos_Assumpt!C29))-(($C$5*F10*B12*(1+Pressupostos_Assumpt!C29))*Pressupostos_Assumpt!C30+$C$6*B12*Pressupostos_Assumpt!C32)-$C$7)*Pressupostos_Assumpt!C56,0) -> 3807.8659 | G12: =(($C$5*G10*B12*(1+Pressupostos_Assumpt!C29))-(($C$5*G10*B12*(1+Pressupostos_Assumpt!C29))*Pressupostos_Assumpt!C30+$C$6*B12*Pressupostos_Assumpt!C32)-$C$7)-IF((($C$5*G10*B12*(1+Pressupostos_Assumpt!C29))-(($C$5*G10*B12*(1+Pressupostos_Assumpt!C29))*Pressupostos_Assumpt!C30+$C$6*B12*Pressupostos_Assumpt!C32)-$C$7)>0,(($C$5*G10*B12*(1+Pressupostos_Assumpt!C29))-(($C$5*G10*B12*(1+Pressupostos_Assumpt!C29))*Pressupostos_Assumpt!C30+$C$6*B12*Pressupostos_Assumpt!C32)-$C$7)*Pressupostos_Assumpt!C56,0) -> 4884.7233
